Workbook

Sheet README
A1: README — Setup Instructions
A3: Step | B3: Action | C3: Details
A4: 1 | B4: Upload this .xlsx to Google Drive | C4: Open it with Google Sheets.
A5: 2 | B5: Open Apps Script | C5: Google Sheets: Extensions → Apps Script.
A6: 3 | B6: Paste the provided .gs script | C6: Delete starter code, paste the script file, then save.
A7: 4 | B7: Authorize once | C7: Run setupScanner once from Apps Script or reload the sheet and use the menu. Google will ask for permissions.
A8: 5 | B8: Register cards | C8: Scan each card somewhere blank to learn the Card_ID, then paste it into Students!A with the student name.
A9: 6 | B9: Use Scan tab | C9: Click Scan!B3, choose a mode, set amount or item ID, then scan.
A10: 7 | B10: Protect tabs | C10: In Google Sheets, protect everything except Scan!B3:B8 if students can access the computer.
A11: 8 | B11: Optional Google Doc reports | C11: Paste a Google Doc ID into Settings and set Report_To_Doc to TRUE.
A13: Important notes
A14: Most RFID/NFC readers act like keyboards. They type the ID into the active cell and may press Enter automatically.
A15: The spreadsheet alone stores structure and formulas. The Apps Script is required for automation.
A16: For STORE_PURCHASE, put the item code in Scan!B7. The script finds the item in the Store tab and subtracts the price.
A17: For attendance, the script prevents duplicate attendance for the same student/date/class period.
A18: Run Payroll from the custom Classroom Scanner menu after the script is installed.
A19: This is built as a practical classroom tool, not a secure financial system. Protect your sheets.
A21: Shared Link: | B21: https://docs.google.com/spreadsheets/d/1m6mpxI00ZamfDDSzu00Cj-SOCvnEm4UrPOwK2-H9_Zc/edit?usp=sharing

Sheet Notification_Queue
A1: Created_At | B1: Date | C1: Type | D1: Message | E1: Status | F1: Attempts | G1: Last_Attempt_At | H1: Last_Error
A2: 46183.605 | B2: 46183 | C2: TEST | D2: ✅ Test notification queued from Apps Script. | E2: Sent | F2: 1 | G2: 46183.605
A3: 46183.645 | B3: 46183 | C3: USE_ITEM | D3: 🎒 *Item Use Recorded* *Student:* Test *Class:* 11 *Card ID:* 1234 *Item:* Homework Pass *Item ID:* 5587 *Quantity Used:* 1 *Remaining:* 0 *Note:* Testing item-use request from Apps Script. Submitted: Jun 10, 2026 3:28 PM | E3: Sent | F3: 1 | G3: 46183.645
A4: 46183.65 | B4: 46183 | C4: USE_ITEM | D4: 🎒 *Item Use Recorded* *Student:* John *Class:* Teacher *Card ID:* 2233 *Item:* +1 Assignment Bonus Token *Item ID:* 3313 *Quantity Used:* 1 *Remaining:* 4 *Note:* Want to use for Homework #2 Submitted: Jun 10, 2026 3:36 PM | E4: Sent | F4: 1 | G4: 46183.651
A5: 46183.654 | B5: 46183 | C5: USE_ITEM | D5: 🎒 *Item Use Recorded* *Student:* Test *Class:* 11 *Card ID:* 1234 *Item:* Open-Note Quiz Pass *Item ID:* 6655 *Quantity Used:* 1 *Remaining:* 0 Submitted: Jun 10, 2026 3:41 PM | E5: Sent | F5: 1 | G5: 46183.654
A6: 46183.871 | B6: 46183 | C6: USE_ITEM | D6: 🎒 *Item Use Recorded* *Student:* Test *Class:* 11 *Card ID:* 1234 *Item:* Insurance Contract *Item ID:* 3965 *Quantity Used:* 1 *Remaining:* 1 Submitted: Jun 10, 2026 8:53 PM | E6: Sent | F6: 1 | G6: 46183.871
A7: 46183.871 | B7: 46183 | C7: USE_ITEM | D7: 🎒 *Item Use Recorded* *Student:* Test *Class:* 11 *Card ID:* 1234 *Item:* Insurance Contract *Item ID:* 3965 *Quantity Used:* 1 *Remaining:* 0 Submitted: Jun 10, 2026 8:53 PM | E7: Sent | F7: 1 | G7: 46183.871
A8: 46184.446 | B8: 46184 | C8: USE_ITEM | D8: 🎒 *Item Use Recorded* *Student:* Suha Lee *Class:* 10 · HS202 *Card ID:* 7c4e261e *Item:* Extra credit 1% *Item ID:* 7734 *Quantity Used:* 6 *Remaining:* 0 *Note:* American Literature Honors increase 6% pls tytyty Submitted: Jun 11, 2026 10:41 AM | E8: Sent | F8: 1 | G8: 46184.446
A9: 46184.449 | B9: 46184 | C9: USE_ITEM | D9: 🎒 *Item Use Recorded* *Student:* Tiffany Kim *Class:* 10 · HS202 *Card ID:* 5c07fef4 *Item:* Extra credit 1% *Item ID:* 7734 *Quantity Used:* 1 *Remaining:* 2 *Note:* econ test grad Submitted: Jun 11, 2026 10:47 AM | E9: Sent | F9: 1 | G9: 46184.45
A10: 46184.45 | B10: 46184 | C10: USE_ITEM | D10: 🎒 *Item Use Recorded* *Student:* Tiffany Kim *Class:* 10 · HS202 *Card ID:* 5c07fef4 *Item:* Extra credit 1% *Item ID:* 7734 *Quantity Used:* 1 *Remaining:* 1 *Note:* same Submitted: Jun 11, 2026 10:48 AM | E10: Sent | F10: 1 | G10: 46184.45
A11: 46184.45 | B11: 46184 | C11: USE_ITEM | D11: 🎒 *Item Use Recorded* *Student:* Tiffany Kim *Class:* 10 · HS202 *Card ID:* 5c07fef4 *Item:* Extra credit 1% *Item ID:* 7734 *Quantity Used:* 1 *Remaining:* 0 *Note:* same Submitted: Jun 11, 2026 10:48 AM | E11: Sent | F11: 1 | G11: 46184.451
A12: 46184.647 | B12: 46184 | C12: USE_ITEM | D12: 🎒 *Item Use Recorded* *Student:* Test *Class:* 11 *Card ID:* 1234 *Item:* Participation Recovery Token *Item ID:* 7898 *Quantity Used:* 1 *Remaining:* 0 Submitted: Jun 11, 2026 3:32 PM | E12: Sent | F12: 1 | G12: 46184.647
A13: 46184.658 | B13: 46184 | C13: USE_ITEM | D13: 🎒 *Item Use Recorded* *Student:* Test *Class:* 11 *Card ID:* 1234 *Item:* Extra credit 1% *Item ID:* 7734 *Quantity Used:* 1 *Remaining:* 0 Submitted: Jun 11, 2026 3:47 PM | E13: Sent | F13: 1 | G13: 46184.659
... A15: 46186.342 | B15: 46186 | C15: USE_ITEM | D15: 🎒 *Item Use Recorded* *Student:* Test *Class:* 11 *Card ID:* 1234 *Item:* Extra credit 1% *Item ID:* 7734 *Quantity Used:* 1 *Remaining:* 0 *Note:* test Submitted: Jun 13, 2026 8:12 AM | E15: Sent | F15: 1 | G15: 46186.343

Sheet Item_Use_Log
A1: Timestamp | B1: Date | C1: Card_ID | D1: Student_Name | E1: Grade | F1: Homeroom | G1: Item_ID | H1: Item_Name | I1: Category | J1: Quantity | K1: Note | L1: Status
A2: 46183.55 | B2: 46183 | C2: 1234 | D2: Test | G2: 5587 | H2: Homework Pass | I2: Academic | J2: 1 | K2: Testing item-use request from api-test-logger.gs | L2: Pending
A3: 46183.563 | B3: 46183 | C3: 1234 | D3: Test | E3: 11 | G3: 5587 | H3: Homework Pass | I3: Academic | J3: 1 | K3: Testing USE_ITEM through apiRouter. | L3: Pending
A4: 46183.57 | B4: 46183 | C4: 1234 | D4: Test | E4: 11 | G4: 5587 | H4: Homework Pass | I4: Academic | J4: 1 | L4: Pending
A5: 46183.571 | B5: 46183 | C5: 1234 | D5: Test | E5: 11 | G5: 5587 | H5: Homework Pass | I5: Academic | J5: 2 | L5: Pending
A6: 46183.574 | B6: 46183 | C6: 1234 | D6: Test | E6: 11 | G6: 5587 | H6: Homework Pass | I6: Academic | J6: 1 | L6: Used
A7: 46183.575 | B7: 46183 | C7: 1234 | D7: Test | E7: 11 | G7: 5587 | H7: Homework Pass | I7: Academic | J7: 1 | L7: Used
A8: 46183.575 | B8: 46183 | C8: 3466 | D8: Jay Kim | E8: 11 | F8: HS211 | G8: 9965 | H8: Market Prediction Report | I8: Bonus | J8: 1 | K8: i wanna use this | L8: Used
A9: 46183.589 | B9: 46183 | C9: 4647 | D9: Jake Kim | E9: 8 | G9: 5587 | H9: Homework Pass | I9: Academic | J9: 1 | L9: Used
A10: 46183.645 | B10: 46183 | C10: 1234 | D10: Test | E10: 11 | G10: 5587 | H10: Homework Pass | I10: Academic | J10: 1 | K10: Testing item-use request from Apps Script. | L10: Used
A11: 46183.65 | B11: 46183 | C11: 2233 | D11: John | E11: Teacher | G11: 3313 | H11: +1 Assignment Bonus Token | I11: Academic | J11: 1 | K11: Want to use for Homework #2 | L11: Used
A12: 46183.654 | B12: 46183 | C12: 1234 | D12: Test | E12: 11 | G12: 6655 | H12: Open-Note Quiz Pass | I12: Academic | J12: 1 | L12: Used
A13: 46183.871 | B13: 46183 | C13: 1234 | D13: Test | E13: 11 | G13: 3965 | H13: Insurance Contract | I13: Bonus | J13: 1 | L13: Used
A14: 46183.871 | B14: 46183 | C14: 1234 | D14: Test | E14: 11 | G14: 3965 | H14: Insurance Contract | I14: Bonus | J14: 1 | L14: Used
A15: 46184.446 | B15: 46184 | C15: 7c4e261e | D15: Suha Lee | E15: 10 | F15: HS202 | G15: 7734 | H15: Extra credit 1% | I15: Academic | J15: 6 | K15: American Literature Honors increase 6% pls tytyty | L15: Used
A16: 46184.449 | B16: 46184 | C16: 5c07fef4 | D16: Tiffany Kim | E16: 10 | F16: HS202 | G16: 7734 | H16: Extra credit 1% | I16: Academic | J16: 1 | K16: econ test grad | L16: Used
A17: 46184.45 | B17: 46184 | C17: 5c07fef4 | D17: Tiffany Kim | E17: 10 | F17: HS202 | G17: 7734 | H17: Extra credit 1% | I17: Academic | J17: 1 | K17: same | L17: Used
A18: 46184.45 | B18: 46184 | C18: 5c07fef4 | D18: Tiffany Kim | E18: 10 | F18: HS202 | G18: 7734 | H18: Extra credit 1% | I18: Academic | J18: 1 | K18: same | L18: Used
A19: 46184.647 | B19: 46184 | C19: 1234 | D19: Test | E19: 11 | G19: 7898 | H19: Participation Recovery Token | I19: Privilege | J19: 1 | L19: Used
A20: 46184.658 | B20: 46184 | C20: 1234 | D20: Test | E20: 11 | G20: 7734 | H20: Extra credit 1% | I20: Academic | J20: 1 | L20: Used
A21: 46185.382 | B21: 46185 | C21: 5a032611 | D21: Harold Dou | E21: 10 | F21: HS202 | G21: 7734 | H21: Extra credit 1% | I21: Academic | J21: 10 | K21: I want to use in American Literature Walden Chapter Analysis Assignment | L21: Used
A22: 46186.342 | B22: 46186 | C22: 1234 | D22: Test | E22: 11 | G22: 7734 | H22: Extra credit 1% | I22: Academic | J22: 1 | K22: test | L22: Used

Sheet Api_Test_Log
A1: Timestamp | B1: Date | C1: Test_Name | D1: Action | E1: Ok | F1: Message | G1: Duration_MS | H1: Request_JSON | I1: Response_JSON | J1: Error | K1: Notes
A2: 46183.543 | B2: 46183 | C2: READ_ONLY_FLOW | D2: LOGIN | E2: TRUE | G2: 4563 | H2: {"action":"LOGIN","accessCode":"***"} | I2: {"ok":true,"token":"a995...8185","profile":{"name":"Test","grade":"","homeroom":"","balance":99800,"jobTitle":"","active":"Yes"},"snapshot":{"hasProfile":true,"storeCount":13,"transactionCount":1,"inventoryCount":1,"marketCount":65,"portfolioCount":1,"ratingCount":0}} | K2: Login returned token.
A3: 46183.543 | B3: 46183 | C3: READ_ONLY_FLOW | D3: GET_SNAPSHOT | E3: TRUE | G3: 3603 | H3: {"action":"GET_SNAPSHOT","token":"a995...8185"} | I3: {"ok":true,"snapshot":{"hasProfile":true,"storeCount":13,"transactionCount":1,"inventoryCount":1,"marketCount":65,"portfolioCount":1,"ratingCount":0}} | K3: Snapshot counts | store=13 | transactions=1 | inventory=1 | market=65 | portfolio=1 | ratings=0
A4: 46183.543 | B4: 46183 | C4: READ_ONLY_FLOW | D4: LOGOUT | E4: TRUE | G4: 52 | H4: {"action":"LOGOUT","token":"a995...8185"} | I4: {"ok":true} | K4: Action completed.
A5: 46183.545 | B5: 46183 | C5: READ_ONLY_FLOW | D5: LOGIN | E5: TRUE | G5: 3656 | H5: {"action":"LOGIN","accessCode":"***"} | I5: {"ok":true,"token":"0470...6c29","profile":{"name":"Test","grade":"","homeroom":"","balance":99800,"jobTitle":"","active":"Yes"},"snapshot":{"hasProfile":true,"storeCount":13,"transactionCount":1,"inventoryCount":1,"marketCount":65,"portfolioCount":1,"ratingCount":0}} | K5: Login returned token.
A6: 46183.545 | B6: 46183 | C6: READ_ONLY_FLOW | D6: GET_SNAPSHOT | E6: TRUE | G6: 3108 | H6: {"action":"GET_SNAPSHOT","token":"0470...6c29"} | I6: {"ok":true,"snapshot":{"hasProfile":true,"storeCount":13,"transactionCount":1,"inventoryCount":1,"marketCount":65,"portfolioCount":1,"ratingCount":0}} | K6: Snapshot counts | store=13 | transactions=1 | inventory=1 | market=65 | portfolio=1 | ratings=0
A7: 46183.545 | B7: 46183 | C7: READ_ONLY_FLOW | D7: LOGOUT | E7: TRUE | G7: 16 | H7: {"action":"LOGOUT","token":"0470...6c29"} | I7: {"ok":true} | K7: Action completed.
A8: 46183.545 | B8: 46183 | C8: SINGLE_ACTION_TEST | D8: LOGIN | E8: TRUE | G8: 7037 | H8: {"action":"LOGIN","accessCode":"***"} | I8: {"ok":true,"token":"0e37...a797","profile":{"name":"Test","grade":"","homeroom":"","balance":99800,"jobTitle":"","active":"Yes"},"snapshot":{"hasProfile":true,"storeCount":13,"transactionCount":1,"inventoryCount":1,"marketCount":65,"portfolioCount":1,"ratingCount":0}} | K8: Login returned token.
A9: 46183.549 | B9: 46183 | C9: FULL_WRITE_FLOW | D9: LOGIN | E9: TRUE | G9: 4538 | H9: {"action":"LOGIN","accessCode":"***"} | I9: {"ok":true,"token":"ad51...92aa","profile":{"name":"Test","grade":"","homeroom":"","balance":99800,"jobTitle":"","active":"Yes"},"snapshot":{"hasProfile":true,"storeCount":13,"transactionCount":1,"inventoryCount":1,"marketCount":65,"portfolioCount":1,"ratingCount":0}} | K9: Login returned token.
A10: 46183.549 | B10: 46183 | C10: FULL_WRITE_FLOW | D10: GET_SNAPSHOT | E10: TRUE | G10: 3410 | H10: {"action":"GET_SNAPSHOT","token":"ad51...92aa"} | I10: {"ok":true,"snapshot":{"hasProfile":true,"storeCount":13,"transactionCount":1,"inventoryCount":1,"marketCount":65,"portfolioCount":1,"ratingCount":0}} | K10: Snapshot counts | store=13 | transactions=1 | inventory=1 | market=65 | portfolio=1 | ratings=0
A11: 46183.549 | B11: 46183 | C11: FULL_WRITE_FLOW | D11: STORE_PURCHASE | E11: TRUE | F11: Purchase completed. | G11: 6396 | H11: {"action":"STORE_PURCHASE","token":"ad51...92aa","payload":{"itemId":"5587","quantity":1}} | I11: {"ok":true,"message":"Purchase completed.","snapshot":{"hasProfile":true,"storeCount":13,"transactionCount":2,"inventoryCount":1,"marketCount":65,"portfolioCount":1,"ratingCount":0}} | K11: Action completed.
A12: 46183.55 | B12: 46183 | C12: FULL_WRITE_FLOW | D12: USE_ITEM | E12: TRUE | F12: Request sent. Your teacher has been notified. | G12: 8929 | H12: {"action":"USE_ITEM","token":"ad51...92aa","payload":{"itemId":"5587","itemName":"Homework Pass","quantity":1,"note":"Testing item-use request from api-test-logger.gs"}} | I12: {"ok":true,"message":"Request sent. Your teacher has been notified.","snapshot":{"hasProfile":true,"storeCount":13,"transactionCount":3,"inventoryCount":1,"marketCount":65,"portfolioCount":1,"ratingCount":0}} | K12: Action completed.
A13: 46183.55 | B13: 46183 | C13: FULL_WRITE_FLOW | D13: STOCK_TRADE | E13: TRUE | F13: Stock purchase completed. | G13: 7353 | H13: {"action":"STOCK_TRADE","token":"ad51...92aa","payload":{"action":"BUY","ticker":"BYTE","shares":1}} | I13: {"ok":true,"message":"Stock purchase completed.","snapshot":{"hasProfile":true,"storeCount":13,"transactionCount":3,"inventoryCount":1,"marketCount":65,"portfolioCount":2,"ratingCount":0}} | K13: Action completed.
A14: 46183.55 | B14: 46183 | C14: FULL_WRITE_FLOW | D14: SUBMIT_RATING | E14: TRUE | F14: Rating submitted. | G14: 5843 | H14: {"action":"SUBMIT_RATING","token":"ad51...92aa","payload":{"ticker":"BYTE","rating":"HOLD","targetPrice":100,"reason":"Testing rating submission from api-test-logger.gs"}} | I14: {"ok":true,"message":"Rating submitted.","snapshot":{"hasProfile":true,"storeCount":13,"transactionCount":3,"inventoryCount":1,"marketCount":65,"portfolioCount":2,"ratingCount":1}} | K14: Action completed.
A15: 46183.55 | B15: 46183 | C15: FULL_WRITE_FLOW | D15: GET_SNAPSHOT | E15: TRUE | G15: 3732 | H15: {"action":"GET_SNAPSHOT","token":"ad51...92aa"} | I15: {"ok":true,"snapshot":{"hasProfile":true,"storeCount":13,"transactionCount":3,"inventoryCount":1,"marketCount":65,"portfolioCount":2,"ratingCount":1}} | K15: Snapshot counts | store=13 | transactions=3 | inventory=1 | market=65 | portfolio=2 | ratings=1
A16: 46183.55 | B16: 46183 | C16: FULL_WRITE_FLOW | D16: LOGOUT | E16: TRUE | G16: 50 | H16: {"action":"LOGOUT","token":"ad51...92aa"} | I16: {"ok":true} | K16: Action completed.

Sheet Scan
A1: Classroom Card Scanner — Balance + Attendance + Store
A3: Scan Card Here | D3: Mode Guide | E3: Uses Amount? | F3: Uses Item_ID?
A4: Mode | B4: ATTENDANCE | D4: ATTENDANCE | E4: No | F4: No
A5: Amount | B5: 100 | D5: DEPOSIT | E5: Yes | F5: No
A6: Class / Period | B6: Homeroom | D6: WITHDRAW | E6: Yes | F6: No
A7: Item_ID | B7: MUSIC01 | D7: REWARD | E7: Yes | F7: No
A8: Note | D8: FINE | E8: Yes | F8: No
D9: STORE_PURCHASE | E9: No | F9: Yes
A10: Last Result | B10: Junjae Park marked Present at 08:31:04 KST. Bonus: +10. | D10: PAYROLL | E10: Run from menu | F10: No
A12: Fast workflow
A13: 1 | B13: Click B3 | C13: Keep the cursor in the yellow scan cell.
A14: 2 | B14: Choose Mode | C14: ATTENDANCE, DEPOSIT, WITHDRAW, REWARD, FINE, or STORE_PURCHASE.
A15: 3 | B15: Set amount/item | C15: Use Amount for money actions. Use Item_ID for store purchases.
A16: 4 | B16: Scan card | C16: The script updates balances, attendance, logs, and dashboard formulas.
A17: 5 | B17: Review result | C17: Last Result tells you what happened.
A18: 6 | B18: Use menu | C18: Classroom Scanner menu can run payroll/reports after script install.

Sheet Dashboard
A1: Dashboard
A3: Total Money Supply | C3: Active Students | E3: Attendance Today | G3: Late Today
A4: =SUM(Students!$E$4:E21) -> 34001.82 | C4: =COUNTIFS(Students!$G$4:G21,"Yes",Students!$A$4:A21,"<>") -> 18 | E4: =COUNTIFS(Daily_Attendance!$A$4:A32,TEXT(TODAY(),"yyyy-mm-dd")) -> 0 | G4: =COUNTIFS(Daily_Attendance!$A$4:A32,TEXT(TODAY(),"yyyy-mm-dd"),Daily_Attendance!$G$4:G32,"Late") -> 0
A6: Money Summary | F6: Attendance Summary
A7: Metric | B7: Value | C7: Formula Meaning | D7: Notes | F7: Metric | G7: Value | H7: Notes
A8: Deposits | B8: {=SUM(SUMIFS(Transactions!$F$4:F27,Transactions!$E$4:E27,{"DEPOSIT","REWARD","PAYROLL","ATTENDANCE_BONUS"},Transactions!$L$4:L27,"Success"))} -> 191 | C8: DEPOSIT + REWARD + PAYROLL + ATTENDANCE_BONUS | D8: Incoming money | F8: Present today | G8: =COUNTIFS( Daily_Attendance!$A$4:A20,TODAY(), Daily_Attendance!$G$4:G20,"Present" ) -> 0 | H8: On-time scans today
A9: Withdrawals | B9: {=SUM(SUMIFS(Transactions!$F$4:F27,Transactions!$E$4:E27,{"WITHDRAW","FINE","STORE_PURCHASE"},Transactions!$L$4:L27,"Success"))} -> 0 | C9: WITHDRAW + FINE + STORE_PURCHASE | D9: Outgoing money | F9: Late today | G9: =COUNTIFS( Daily_Attendance!$A$4:A20,TODAY(), Daily_Attendance!$G$4:G20,"Late" ) -> 0 | H9: Late scans today
A10: Store purchases | B10: =COUNTIFS(Transactions!$E$4:E27,"STORE_PURCHASE",Transactions!$L$4:L27,"Success") -> 0 | C10: Count of successful store purchases | F10: Absent today | G10: =COUNTIF(Students!$G$4:G20,"Yes")- COUNTIFS(Daily_Attendance!$A$4:A20,TODAY(),Daily_Attendance!$G$4:G20,"Present")- COUNTIFS(Daily_Attendance!$A$4:A20,TODAY(),Daily_Attendance!$G$4:G20,"Late") -> 76 | H10: Active students minus today's attendance
A11: Rewards | B11: =COUNTIFS(Transactions!$E$4:E27,"REWARD",Transactions!$L$4:L27,"Success") -> 15 | C11: Count of reward deposits | F11: Attendance rate | G11: =IFERROR(COUNTIFS(Daily_Attendance!$A$4:A20,TEXT(TODAY(),"yyyy-mm-dd"))/COUNTIFS(Students!$G$4:G20,"Yes",Students!$A$4:A20,"<>"),0) -> 0 | H11: Today attendance / active students
A12: Fines | B12: =COUNTIFS(Transactions!$E$4:E27,"FINE",Transactions!$L$4:L27,"Success") -> 0 | C12: Count of fine withdrawals | F12: Total attendance scans | G12: =COUNTA(Daily_Attendance!$A$4:A32) -> 29 | H12: All-time daily records
A13: Failed/Denied transactions | B13: =COUNTIFS(Transactions!$L$4:L27,"<>Success",Transactions!$L$4:L27,"<>") -> 2 | C13: Status is not Success
A15: Top Balances | F15: Quick Reminders
A16: Student | B16: Balance | F16: Step | G16: Reminder | H16: Why it matters
A17: =IFERROR(__xludf.DUMMYFUNCTION("IFNA(SORTN(FILTER({Students!$B$4:$B$21,Students!$E$4:$E$21},Students!$B$4:$B$21<>"""",Students!$E$4:$E$21<>""""),4,0,2,FALSE),"""")"),"Hannah") -> Hannah | B17: =IFERROR(__xludf.DUMMYFUNCTION("""COMPUTED_VALUE"""),10028.2) -> 10028.2 | F17: 1 | G17: Protect tabs except Scan | H17: Stops students from editing balances.
A18: =IFERROR(__xludf.DUMMYFUNCTION("""COMPUTED_VALUE"""),"Ellie") -> Ellie | B18: =IFERROR(__xludf.DUMMYFUNCTION("""COMPUTED_VALUE"""),8764.1) -> 8764.1 | F18: 2 | G18: Keep cursor in Scan!B3 | H18: Most card readers type like keyboards.
A19: =IFERROR(__xludf.DUMMYFUNCTION("""COMPUTED_VALUE"""),"DK") -> DK | B19: =IFERROR(__xludf.DUMMYFUNCTION("""COMPUTED_VALUE"""),8404.61) -> 8404.61 | F19: 3 | G19: Register every card first | H19: Unknown cards are denied and logged.
A20: =IFERROR(__xludf.DUMMYFUNCTION("""COMPUTED_VALUE"""),"Ruby") -> Ruby | B20: =IFERROR(__xludf.DUMMYFUNCTION("""COMPUTED_VALUE"""),1827.26) -> 1827.26 | F20: 4 | G20: Use menu for payroll/reports | H20: Menu appears after script install.

Sheet Students
A1: Students / Card Registry
A3: Card_ID | B3: Student_Name | C3: Grade | D3: Homeroom | E3: Balance | F3: Job_Title | G3: Active | H3: Last_Updated | I3: Attendance_Streak | J3: Last_Attendance_Date | K3: Notes
A4: ba353911 | B4: Dayeon Kang | C4: 10 | D4: HS202 | E4: 341.98 | F4: - | G4: Yes | H4: 46184.357 | I4: 4 | J4: 46184
A5: dc04eef4 | B5: Joshua Jung | C5: 10 | D5: HS202 | E5: 234.86 | F5: - | G5: Yes | H5: 46185.354 | I5: 5 | J5: 46185
A6: 5a032611 | B6: Harold Dou | C6: 10 | D6: HS202 | E6: 198 | F6: - | G6: Yes | H6: 46184.606 | I6: 1 | J6: 46184
A7: 7c4e261e | B7: Suha Lee | C7: 10 | D7: HS202 | E7: 49.83 | F7: - | G7: Yes | H7: 46185.351 | I7: 4 | J7: 46185
A8: ba0fc5c4 | B8: Junwoo Kang | C8: 10 | D8: HS202 | E8: 4.19 | F8: - | G8: Yes | H8: 46184.501 | I8: 0 | J8: 46181
A9: ba912211 | B9: Daisy Doh | C9: 10 | D9: HS202 | E9: 483.88 | F9: - | G9: Yes | H9: 46185.346 | I9: 5 | J9: 46185
A10: 5c07fef4 | B10: Tiffany Kim | C10: 10 | D10: HS202 | E10: 430 | F10: - | G10: Yes | H10: 46185.346 | I10: 5 | J10: 46185
A11: babde4c4 | B11: Ashley Guk | C11: 10 | D11: HS202 | E11: 616 | F11: - | G11: Yes | H11: 46184.356 | I11: 1 | J11: 46184
A12: ae072910 | B12: Selena Jung | C12: 10 | D12: HS202 | E12: 353.79 | F12: - | G12: Yes | H12: 46184.351 | I12: 4 | J12: 46184
A13: 1e3e1410 | B13: Junjae Park | C13: 10 | D13: HS202 | E13: 27.98 | F13: - | G13: Yes | H13: 46185.649 | I13: 5 | J13: 46185
A14: 9a5f2811 | B14: Junyoung Yoo | C14: 10 | D14: HS202 | E14: 46.86 | F14: - | G14: Yes | H14: 46184.468 | I14: 0 | J14: 46183
A15: 1321 | B15: Ahin | C15: 7 | D15: HS202 | E15: 743.61 | F15: - | G15: Yes | H15: 46186.437
A16: 4673 | B16: Ellie | C16: 7 | D16: HS203 | E16: 8764.1 | F16: - | G16: Yes | H16: 46185.535
A17: 2217 | B17: DK | C17: 7 | D17: HS204 | E17: 8404.61 | F17: - | G17: Yes | H17: 46185.68
A18: 1978 | B18: Hannah | C18: 7 | D18: HS205 | E18: 10028.2 | F18: - | G18: Yes | H18: 46178.542
A19: 1876 | B19: Lena | C19: 7 | D19: HS206 | E19: 311.09 | F19: - | G19: Yes | H19: 46185.579
A20: 8765 | B20: Minjun | C20: 7 | D20: HS207 | E20: 1135.58 | F20: - | G20: Yes | H20: 46187.402
A21: 9887 | B21: Ruby | C21: 7 | D21: HS208 | E21: 1827.26 | F21: - | G21: Yes | H21: 46185.524
A22: 7765 | B22: Yeonju | C22: 7 | D22: HS209 | E22: 5263.92 | F22: - | G22: Yes | H22: 46185.448
A23: 6665 | B23: Jinwoo | C23: 7 | D23: HS210 | E23: 1553.49 | F23: - | G23: Yes | H23: 46185.537
A24: 8989 | B24: Oakley | C24: 7 | D24: HS211 | E24: 7002.67 | F24: - | G24: Yes | H24: 46185.535
A25: 1234 | B25: Test | C25: 11 | E25: 95.34 | F25: - | G25: Yes | H25: 46186.699
A26: 8244 | B26: Alexis Parisee | C26: 11 | D26: HS203 | E26: 1000 | F26: - | G26: Yes
A27: 3846 | B27: Jace Kim | C27: 11 | D27: HS204 | E27: 1893.12 | F27: - | G27: Yes | H27: 46184.385
A28: 2659 | B28: Jin Park | C28: 11 | D28: HS205 | E28: 3.56 | F28: - | G28: Yes | H28: 46183.572
A29: 7302 | B29: Claire Yang | C29: 11 | D29: HS206 | E29: 43.05 | F29: - | G29: Yes | H29: 46183.578
A30: 5420 | B30: Daniel Park | C30: 11 | D30: HS207 | E30: 5.81 | F30: - | G30: Yes | H30: 46185.623
A31: 4098 | B31: Anthony Ahn | C31: 11 | D31: HS208 | E31: 1000 | F31: - | G31: Yes
A32: 9908 | B32: Alex Kang | C32: 11 | D32: HS209 | E32: 1000 | F32: - | G32: Yes
A33: 8601 | B33: Mathew Kim | C33: 11 | D33: HS210 | E33: 1000 | F33: - | G33: Yes
A34: 3466 | B34: Jay Kim | C34: 11 | D34: HS211 | E34: 130.35 | F34: - | G34: Yes | H34: 46183.648
A35: 8300 | B35: Andy Lee | C35: 11 | D35: HS212 | E35: 27.22 | F35: - | G35: Yes | H35: 46183.573
A36: 1688 | B36: Junwoo Yoon | C36: 11 | D36: HS213 | E36: 168.92 | F36: - | G36: Yes | H36: 46183.684
A37: 8045 | B37: Hyunmo Gu | C37: 11 | D37: HS214 | E37: 1000 | F37: - | G37: Yes
A38: 1926 | B38: Sooin Kang | C38: 11 | D38: HS215 | E38: 1000 | F38: - | G38: Yes
A39: 1035 | B39: Jiwon Kang | C39: 11 | D39: HS216 | E39: 1000 | F39: - | G39: Yes
A40: 3706 | B40: Kevin Jeon | C40: 11 | D40: HS217 | E40: 107.95 | F40: - | G40: Yes | H40: 46183.592
A41: 1117 | B41: Hyeonjun Kim | C41: 8 | E41: 48.17 | F41: - | G41: Yes | H41: 46185.659
...

Sheet Transactions
A1: Money / Store Transaction Log
A3: Timestamp | B3: Date | C3: Card_ID | D3: Student_Name | E3: Mode | F3: Amount | G3: Starting_Balance | H3: Ending_Balance | I3: Item_ID | J3: Item_Name | K3: Note | L3: Status
A4: 46163.347 | B4: 46163 | C4: 5c07fef4 | D4: Tiffany Kim | E4: REWARD | F4: 10 | G4: 0 | H4: 10 | K4: On-time attendance reward | L4: Success
A5: 46163.348 | B5: 46163 | C5: babde4c4 | D5: Ashley Guk | E5: REWARD | F5: 10 | G5: 0 | H5: 10 | K5: On-time attendance reward | L5: Success
A6: 46164.348 | B6: 46164 | C6: ba912211 | D6: Daisy Dou | E6: REWARD | F6: 10 | G6: 0 | H6: 10 | K6: On-time attendance reward | L6: Success
A7: 46163.349 | B7: 46163 | C7: dc04eef4 | D7: Joshua Jung | E7: REWARD | F7: 10 | G7: 0 | H7: 10 | K7: On-time attendance reward | L7: Success
A8: 46163.356 | B8: 46163 | C8: 5a032611 | D8: Harold Dou | E8: REWARD | F8: 10 | G8: 0 | H8: 10 | K8: On-time attendance reward | L8: Success
A9: 46163.356 | B9: 46163 | C9: ba353911 | D9: Dayeon Kang | E9: REWARD | F9: 10 | G9: 0 | H9: 10 | K9: On-time attendance reward | L9: Success
A10: 46164.356 | B10: 46164 | C10: 7c4e261e | D10: Suha Lee | E10: REWARD | F10: 10 | G10: 0 | H10: 10 | K10: On-time attendance reward | L10: Success
A11: 46163.367 | B11: 46163 | C11: 9a5f2811 | D11: Junyoung Yoo | E11: FINE | F11: 10 | G11: 0 | H11: 0 | K11: Late attendance penalty | L11: Denied - insufficient balance
A12: 46164.367 | B12: 46164 | C12: 1e3e1410 | D12: Junjae Park | E12: FINE | F12: 10 | G12: 0 | H12: 0 | K12: Late attendance penalty | L12: Denied - insufficient balance
A13: 46163.465 | B13: 46163 | C13: 9a5f2811 | D13: Junyoung Yoo | E13: DEPOSIT | F13: 20 | G13: 0 | H13: 20 | L13: Success
A14: 46163.468 | B14: 46163 | C14: 7c4e261e | D14: Suha Lee | E14: DEPOSIT | F14: 20 | G14: 10 | H14: 30 | L14: Success
A15: 46163.47 | B15: 46163 | C15: 5a032611 | D15: Harold Dou | E15: DEPOSIT | F15: 20 | G15: 10 | H15: 30 | L15: Success
A16: 46163.472 | B16: 46163 | C16: babde4c4 | D16: Ashley Guk | E16: DEPOSIT | F16: 20 | G16: 10 | H16: 30 | L16: Success
A17: 46163.474 | B17: 46163 | C17: dc04eef4 | D17: Joshua Jung | E17: DEPOSIT | F17: 20 | G17: 10 | H17: 30 | L17: Success
A18: 46163.475 | B18: 46163 | C18: 1e3e1410 | D18: Junjae Park | E18: DEPOSIT | F18: 20 | G18: 0 | H18: 20 | L18: Success
A19: 46164.345 | B19: 46164 | C19: 5c07fef4 | D19: Tiffany Kim | E19: REWARD | F19: 10 | G19: 10 | H19: 20 | K19: On-time attendance reward | L19: Success
A20: 46164.353 | B20: 46164 | C20: dc04eef4 | D20: Joshua Jung | E20: REWARD | F20: 10 | G20: 30 | H20: 40 | K20: On-time attendance reward | L20: Success
A21: 46164.353 | B21: 46164 | C21: ba912211 | D21: Daisy Dou | E21: REWARD | F21: 10 | G21: 10 | H21: 20 | K21: On-time attendance reward | L21: Success
A22: 46164.354 | B22: 46164 | C22: babde4c4 | D22: Ashley Guk | E22: REWARD | F22: 10 | G22: 30 | H22: 40 | K22: On-time attendance reward | L22: Success
A23: 46164.354 | B23: 46164 | C23: 7c4e261e | D23: Suha Lee | E23: REWARD | F23: 10 | G23: 30 | H23: 40 | K23: On-time attendance reward | L23: Success
A24: 46164.357 | B24: 46164 | C24: ba353911 | D24: Dayeon Kang | E24: REWARD | F24: 10 | G24: 10 | H24: 20 | K24: On-time attendance reward | L24: Success
A25: 46164.357 | B25: 46164 | C25: 5a032611 | D25: Harold Dou | E25: REWARD | F25: 10 | G25: 30 | H25: 40 | K25: On-time attendance reward | L25: Success
A26: 46164.357 | B26: 46164 | C26: 9a5f2811 | D26: Junyoung Yoo | E26: REWARD | F26: 10 | G26: 20 | H26: 30 | K26: On-time attendance reward | L26: Success
A27: 46164.359 | B27: 46164 | C27: ba912211 | D27: Daisy Dou | E27: DEPOSIT | F27: 71 | G27: 20 | H27: 91 | L27: Success
A28: 46164.359 | B28: 46164 | C28: babde4c4 | D28: Ashley Guk | E28: DEPOSIT | F28: 16 | G28: 40 | H28: 56 | L28: Success
A29: 46168.339 | B29: 46168 | C29: dc04eef4 | D29: Joshua Jung | E29: REWARD | F29: 10 | G29: 40 | H29: 50 | K29: On-time attendance reward | L29: Success
A30: 46168.351 | B30: 46168 | C30: 5c07fef4 | D30: Tiffany Kim | E30: REWARD | F30: 10 | G30: 20 | H30: 30 | K30: On-time attendance reward | L30: Success
A31: 46168.352 | B31: 46168 | C31: ba912211 | D31: Daisy Dou | E31: REWARD | F31: 10 | G31: 91 | H31: 101 | K31: On-time attendance reward | L31: Success
A32: 46168.355 | B32: 46168 | C32: 7c4e261e | D32: Suha Lee | E32: REWARD | F32: 10 | G32: 40 | H32: 50 | K32: On-time attendance reward | L32: Success
A33: 46168.356 | B33: 46168 | C33: 5a032611 | D33: Harold Dou | E33: REWARD | F33: 10 | G33: 40 | H33: 50 | K33: On-time attendance reward | L33: Success
A34: 46168.356 | B34: 46168 | C34: 9a5f2811 | D34: Junyoung Yoo | E34: REWARD | F34: 10 | G34: 30 | H34: 40 | K34: On-time attendance reward | L34: Success
A35: 46168.359 | B35: 46168 | C35: ba353911 | D35: Dayeon Kang | E35: FINE | F35: 10 | G35: 20 | H35: 10 | K35: Late attendance penalty | L35: Success
A36: 46168.494 | B36: 46168 | C36: ae072910 | D36: Selena Jung | E36: FINE | F36: 10 | G36: 0 | H36: 0 | K36: Late attendance penalty | L36: Denied - insufficient balance
A37: 46168.65 | B37: 46168 | C37: ba0fc5c4 | D37: Junwoo Kang | E37: FINE | F37: 10 | G37: 0 | H37: 0 | K37: Late attendance penalty | L37: Denied - insufficient balance
A38: 46170.347 | B38: 46170 | C38: ae072910 | D38: Selena Jung | E38: REWARD | F38: 10 | G38: 0 | H38: 10 | K38: On-time attendance reward | L38: Success
A39: 46170.35 | B39: 46170 | C39: 5c07fef4 | D39: Tiffany Kim | E39: REWARD | F39: 10 | G39: 30 | H39: 40 | K39: On-time attendance reward | L39: Success
A40: 46170.352 | B40: 46170 | C40: ba912211 | D40: Daisy Dou | E40: REWARD | F40: 10 | G40: 101 | H40: 111 | K40: On-time attendance reward | L40: Success
... A82: 46178.345 | B82: 46178 | C82: 5c07fef4 | D82: Tiffany Kim | E82: REWARD | F82: 10 | G82: 70 | H82: 80 | K82: On-time attendance reward | L82: Success
...

Sheet Attendance_Log
A1: Raw Attendance Scan Log
A3: Timestamp | B3: Date | C3: Card_ID | D3: Student_Name | E3: Grade | F3: Homeroom | G3: Class_Period | H3: Status | I3: Check_In_Time | J3: Streak_After_Scan | K3: Bonus_Applied | L3: Note | M3: System_Status
A4: 46163.347 | B4: 46163 | C4: 5c07fef4 | D4: Tiffany Kim | E4: 10 | F4: HS202 | G4: Homeroom | H4: Present | I4: 0.34707176 | J4: 1 | K4: 10 | L4: On-time reward applied | M4: Success
A5: 46163.348 | B5: 46163 | C5: ba912211 | D5: Daisy Dou | E5: 10 | F5: HS202 | G5: Homeroom | H5: Present | I5: 0.34822917 | J5: 1 | K5: 10 | L5: On-time reward applied | M5: Success
A6: 46163.348 | B6: 46163 | C6: babde4c4 | D6: Ashley Guk | E6: 10 | F6: HS202 | G6: Homeroom | H6: Present | I6: 0.34844907 | J6: 1 | K6: 10 | L6: On-time reward applied | M6: Success
A7: 46163.349 | B7: 46163 | C7: dc04eef4 | D7: Joshua Jung | E7: 10 | F7: HS202 | G7: Homeroom | H7: Present | I7: 0.34944444 | J7: 1 | K7: 10 | L7: On-time reward applied | M7: Success
A8: 46163.356 | B8: 46163 | C8: 5a032611 | D8: Harold Dou | E8: 10 | F8: HS202 | G8: Homeroom | H8: Present | I8: 0.35587963 | J8: 1 | K8: 10 | L8: On-time reward applied | M8: Success
A9: 46163.356 | B9: 46163 | C9: 7c4e261e | D9: Suha Lee | E9: 10 | F9: HS203 | G9: Homeroom | H9: Present | I9: 0.3975463 | J9: 1 | K9: 10 | L9: On-time reward applied | M9: Success
A10: 46163.356 | B10: 46163 | C10: ba353911 | D10: Dayeon Kang | E10: 10 | F10: HS202 | G10: Homeroom | H10: Present | I10: 0.35622685 | J10: 1 | K10: 10 | L10: On-time reward applied | M10: Success
A11: 46163.36 | B11: 46163 | C11: 7c4e261e | D11: Suha Lee | E11: 10 | F11: HS202 | G11: Homeroom | H11: Duplicate | I11: 0.35988426 | K11: 0 | L11: Duplicate scan | M11: Denied - duplicate attendance
A12: 46163.363 | B12: 46163 | C12: 1e3e1410 | D12: Junjae Park | E12: 10 | F12: HS202 | G12: Homeroom | H12: Late | I12: 0.36289352 | J12: 0 | K12: 0 | L12: Late scan | M12: Success
A13: 46163.367 | B13: 46163 | C13: 9a5f2811 | D13: Junyoung Yoo | E13: 10 | F13: HS202 | G13: Homeroom | H13: Late | I13: 0.36681713 | J13: 0 | K13: 0 | L13: Late penalty not applied: insufficient balance | M13: Success
A14: 46164.345 | B14: 46164 | C14: 5c07fef4 | D14: Tiffany Kim | E14: 10 | F14: HS202 | G14: Homeroom | H14: Present | I14: 0.34453704 | J14: 2 | K14: 10 | L14: On-time reward applied | M14: Success
A15: 46164.353 | B15: 46164 | C15: dc04eef4 | D15: Joshua Jung | E15: 10 | F15: HS202 | G15: Homeroom | H15: Present | I15: 0.35334491 | J15: 2 | K15: 10 | L15: On-time reward applied | M15: Success
A16: 46164.353 | B16: 46164 | C16: ba912211 | D16: Daisy Dou | E16: 10 | F16: HS202 | G16: Homeroom | H16: Present | I16: 0.3534838 | J16: 2 | K16: 10 | L16: On-time reward applied | M16: Success
A17: 46164.354 | B17: 46164 | C17: babde4c4 | D17: Ashley Guk | E17: 10 | F17: HS202 | G17: Homeroom | H17: Present | I17: 0.35361111 | J17: 2 | K17: 10 | L17: On-time reward applied | M17: Success
A18: 46164.354 | B18: 46164 | C18: 7c4e261e | D18: Suha Lee | E18: 10 | F18: HS202 | G18: Homeroom | H18: Present | I18: 0.35439815 | J18: 2 | K18: 10 | L18: On-time reward applied | M18: Success
A19: 46164.357 | B19: 46164 | C19: ba353911 | D19: Dayeon Kang | E19: 10 | F19: HS202 | G19: Homeroom | H19: Present | I19: 0.35686343 | J19: 2 | K19: 10 | L19: On-time reward applied | M19: Success
A20: 46164.357 | B20: 46164 | C20: 5a032611 | D20: Harold Dou | E20: 10 | F20: HS202 | G20: Homeroom | H20: Present | I20: 0.35702546 | J20: 2 | K20: 10 | L20: On-time reward applied | M20: Success
A21: 46164.357 | B21: 46164 | C21: 9a5f2811 | D21: Junyoung Yoo | E21: 10 | F21: HS202 | G21: Homeroom | H21: Present | I21: 0.35715278 | J21: 1 | K21: 10 | L21: On-time reward applied | M21: Success
A22: 46168.339 | B22: 46168 | C22: dc04eef4 | D22: Joshua Jung | E22: 10 | F22: HS202 | G22: Homeroom | H22: Present | I22: 0.33902778 | J22: 1 | K22: 10 | L22: On-time reward applied | M22: Success
A23: 46168.351 | B23: 46168 | C23: 5c07fef4 | D23: Tiffany Kim | E23: 10 | F23: HS202 | G23: Homeroom | H23: Present | I23: 0.35086806 | J23: 1 | K23: 10 | L23: On-time reward applied | M23: Success
... A30: 46168.65 | B30: 46168 | C30: ba0fc5c4 | D30: Junwoo Kang | E30: 10 | F30: HS202 | G30: Homeroom | H30: Late | I30: 0.65002315 | J30: 0 | K30: 0 | L30: Late penalty not applied: insufficient balance | M30: Success
A31: 46169.373 | B31: 46169 | C31: ba353911 | D31: Dayeon Kang | E31: 10 | F31: HS202 | G31: Homeroom | H31: Duplicate | I31: 0.37300926 | K31: 0 | L31: Duplicate scan | M31: Denied - duplicate attendance
A32: 46170.347 | B32: 46170 | C32: ae072910 | D32: Selena Jung | E32: 10 | F32: HS202 | G32: Homeroom | H32: Present | I32: 0.34717593 | J32: 1 | K32: 10 | L32: On-time reward applied | M32: Success
A33: 46170.35 | B33: 46170 | C33: 5c07fef4 | D33: Tiffany Kim | E33: 10 | F33: HS202 | G33: Homeroom | H33: Present | I33: 0.35011574 | J33: 1 | K33: 10 | L33: On-time reward applied | M33: Success
A34: 46170.352 | B34: 46170 | C34: ba912211 | D34: Daisy Dou | E34: 10 | F34: HS202 | G34: Homeroom | H34: Present | I34: 0.35193287 | J34: 1 | K34: 10 | L34: On-time reward applied | M34: Success
A35: 46170.352 | B35: 46170 | C35: 7c4e261e | D35: Suha Lee | E35: 10 | F35: HS202 | G35: Homeroom | H35: Present | I35: 0.35211806 | J35: 1 | K35: 10 | L35: On-time reward applied | M35: Success
A36: 46170.352 | B36: 46170 | C36: dc04eef4 | D36: Joshua Jung | E36: 10 | F36: HS202 | G36: Homeroom | H36: Present | I36: 0.35226852 | J36: 1 | K36: 10 | L36: On-time reward applied | M36: Success
A37: 46170.354 | B37: 46170 | C37: babde4c4 | D37: Ashley Guk | E37: 10 | F37: HS202 | G37: Homeroom | H37: Present | I37: 0.35403935 | J37: 1 | K37: 10 | L37: On-time reward applied | M37: Success
A38: 46170.356 | B38: 46170 | C38: ba353911 | D38: Dayeon Kang | E38: 10 | F38: HS202 | G38: Homeroom | H38: Present | I38: 0.35628472 | J38: 1 | K38: 10 | L38: On-time reward applied | M38: Success
A39: 46170.358 | B39: 46170 | C39: 9a5f2811 | D39: Junyoung Yoo | E39: 10 | F39: HS202 | G39: Homeroom | H39: Present | I39: 0.35795139 | J39: 1 | K39: 10 | L39: On-time reward applied | M39: Success
A40: 46170.372 | B40: 46170 | C40: 1e3e1410 | D40: Junjae Park | E40: 10 | F40: HS202 | G40: Homeroom | H40: Late | I40: 0.3725 | J40: 0 | K40: 0 | L40: Late penalty applied | M40: Success
A41: 46170.373 | B41: 46170 | C41: ba0fc5c4 | D41: Junwoo Kang | E41: 10 | F41: HS202 | G41: Homeroom | H41: Late | I41: 0.37265046 | J41: 0 | K41: 0 | L41: Late penalty not applied: insufficient balance | M41: Success
A42: 46174.348 | B42: 46174 | C42: ae072910 | D42: Selena Jung | E42: 10 | F42: HS202 | G42: Homeroom | H42: Present | I42: 0.34792824 | J42: 1 | K42: 10 | L42: On-time reward applied | M42: Success
A43: 46174.348 | B43: 46174 | C43: 5c07fef4 | D43: Tiffany Kim | E43: 10 | F43: HS202 | G43: Homeroom | H43: Present | I43: 0.34815972 | J43: 1 | K43: 10 | L43: On-time reward applied | M43: Success
... A69: 46177.357 | B69: 46177 | C69: 7c4e261e | D69: Suha Lee | E69: 10 | F69: HS202 | G69: Homeroom | H69: Present | I69: 0.35652778 | J69: 1 | K69: 10 | L69: On-time reward applied | M69: Success
A70: 46177.358 | B70: 46177 | C70: bf93598d | D70: UNKNOWN | G70: Homeroom | H70: Unknown Card | I70: 0.35753472 | K70: 0 | M70: Denied - card not registered
A71: 46177.358 | B71: 46177 | C71: 1e3e1410 | D71: Junjae Park | E71: 10 | F71: HS202 | G71: Homeroom | H71: Present | I71: 0.35766204 | J71: 1 | K71: 10 | L71: On-time reward applied | M71: Success
A72: 46177.358 | B72: 46177 | C72: 5a032611 | D72: Harold Dou | E72: 10 | F72: HS202 | G72: Homeroom | H72: Present | I72: 0.35799769 | J72: 1 | K72: 10 | L72: On-time reward applied | M72: Success
...

Sheet Daily_Attendance
A1: Daily Attendance Summary
A4: 46168 | B4: ba912211 | C4: Daisy Dou | D4: 10 | E4: HS202 | F4: Homeroom | G4: Present | H4: 0.35162037 | I4: 1 | J4: 10 | K4: On-time reward applied
A5: 46168 | B5: 7c4e261e | C5: Suha Lee | D5: 10 | E5: HS202 | F5: Homeroom | G5: Present | H5: 0.35445602 | I5: 1 | J5: 10 | K5: On-time reward applied
A6: 46168 | B6: 5a032611 | C6: Harold Dou | D6: 10 | E6: HS202 | F6: Homeroom | G6: Present | H6: 0.35590278 | I6: 1 | J6: 10 | K6: On-time reward applied
A7: 46168 | B7: 9a5f2811 | C7: Junyoung Yoo | D7: 10 | E7: HS202 | F7: Homeroom | G7: Present | H7: 0.35626157 | I7: 1 | J7: 10 | K7: On-time reward applied
A8: 46168 | B8: ba353911 | C8: Dayeon Kang | D8: 10 | E8: HS202 | F8: Homeroom | G8: Late | H8: 0.35865741 | I8: 0 | J8: 0 | K8: Late penalty applied
A9: 46168 | B9: ae072910 | C9: Selena Jung | D9: 10 | E9: HS202 | F9: Homeroom | G9: Late | H9: 0.49429398 | I9: 0 | J9: 0 | K9: Late penalty not applied: insufficient balance
A10: 46168 | B10: ba0fc5c4 | C10: Junwoo Kang | D10: 10 | E10: HS202 | F10: Homeroom | G10: Late | H10: 0.65002315 | I10: 0 | J10: 0 | K10: Late penalty not applied: insufficient balance
A11: 46170 | B11: ae072910 | C11: Selena Jung | D11: 10 | E11: HS202 | F11: Homeroom | G11: Present | H11: 0.34717593 | I11: 1 | J11: 10 | K11: On-time reward applied
A12: 46170 | B12: 5c07fef4 | C12: Tiffany Kim | D12: 10 | E12: HS202 | F12: Homeroom | G12: Present | H12: 0.35011574 | I12: 1 | J12: 10 | K12: On-time reward applied
A13: 46170 | B13: ba912211 | C13: Daisy Dou | D13: 10 | E13: HS202 | F13: Homeroom | G13: Present | H13: 0.35193287 | I13: 1 | J13: 10 | K13: On-time reward applied
A14: 46170 | B14: 7c4e261e | C14: Suha Lee | D14: 10 | E14: HS202 | F14: Homeroom | G14: Present | H14: 0.35211806 | I14: 1 | J14: 10 | K14: On-time reward applied
A15: 46170 | B15: dc04eef4 | C15: Joshua Jung | D15: 10 | E15: HS202 | F15: Homeroom | G15: Present | H15: 0.35226852 | I15: 1 | J15: 10 | K15: On-time reward applied
... A102: 46185 | B102: 1e3e1410 | C102: Junjae Park | D102: 10 | E102: HS202 | F102: Homeroom | G102: Present | H102: 0.35490741 | I102: 5 | J102: 10 | K102: On-time reward applied

Sheet Store
A1: Classroom Store
A3: Item_ID | B3: Item_Name | C3: Price | D3: Active | E3: Inventory | F3: Category | G3: Description
A4: 5896 | B4: Snack Pass | C4: 50 | D4: No | E4: 0 | F4: Reward | G4: Student can eat snacks in the classroom
A5: 5587 | B5: Homework Pass | C5: 200 | D5: No | E5: 0 | F5: Academic | G5: Student may use one limited homework pass, subject to teacher approval.
A6: 3965 | B6: Insurance Contract | C6: 100 | D6: No | E6: 8 | F6: Bonus | G6: Protects the student from one negative market event.
A7: 9965 | B7: Market Prediction Report | C7: 100 | D7: No | E7: 0 | F7: Bonus | G7: Provides one market prediction news article before the next market update.
A8: 2241 | B8: Relaxation Pass | C8: 100 | D8: No | E8: 0 | F8: Privilege | G8: Allows the student to take one short rest period during class.
A9: 3487 | B9: Preferred Seating Pass | C9: 100 | D9: No | E9: 0 | F9: Privilege | G9: Student may choose their seat for one class period.
A10: 6655 | B10: Open-Note Quiz Pass | C10: 100 | D10: No | E10: 2 | F10: Academic | G10: Student may use their own notes during one quiz.
A11: 7898 | B11: Participation Recovery Token | C11: 100 | D11: No | E11: 4 | F11: Privilege | G11: Student may reserve a preferred seat for one class period.
A12: 3313 | B12: +1 Assignment Bonus Token | C12: 100 | D12: No | E12: 3 | F12: Academic | G12: Adds 1 bonus point to one eligible assignment.
A13: 4478 | B13: Assignment Pass | C13: 100 | D13: No | E13: 10 | F13: Academic | G13: Adds 1 bonus point to one eligible assignment.
A14: 3649 | B14: Test Retake | C14: 100 | D14: No | E14: 10 | F14: Academic
A15: 7589 | B15: Essay pass | C15: 100 | D15: No | E15: 10 | F15: Academic
A16: 3345 | B16: Assignment Extention | C16: 100 | D16: No | E16: 10 | F16: Academic
A17: 7734 | B17: Extra credit 1% | C17: 100 | D17: Yes | E17: 76 | F17: Academic | G17: Get 1% extra credit on an assignment

Sheet Student_Inventory
A1: Student Inventory
A3: Card_ID | B3: Student_Name | C3: Item_ID | D3: Item_Name | E3: Category | F3: Quantity_Purchased | G3: Total_Spent | H3: Last_Purchased | I3: Last_Updated
A4: ae072910 | B4: Selena Jung | C4: 9965 | D4: Market Prediction Report | E4: Bonus | F4: 1 | G4: 100 | H4: 46183.496 | I4: 46183.496
A5: 1234 | B5: Test | C5: 5587 | D5: Homework Pass | E5: Academic | F5: 0 | G5: 600 | H5: 46183.58 | I5: 46183.645
A6: 7302 | B6: Claire Yang | C6: 5587 | D6: Homework Pass | E6: Academic | F6: 4 | G6: 800 | H6: 46183.556 | I6: 46183.556
A7: 3466 | B7: Jay Kim | C7: 9965 | D7: Market Prediction Report | E7: Bonus | F7: 0 | G7: 100 | H7: 46183.554 | I7: 46183.575
A8: 7302 | B8: Claire Yang | C8: 2241 | D8: Relaxation Pass | E8: Privilege | F8: 1 | G8: 100 | H8: 46183.554 | I8: 46183.554
A9: 8300 | B9: Andy Lee | C9: 3313 | D9: +1 Assignment Bonus Token | E9: Academic | F9: 2 | G9: 200 | H9: 46183.555 | I9: 46183.555
A10: 7302 | B10: Claire Yang | C10: 6655 | D10: Open-Note Quiz Pass | E10: Academic | F10: 1 | G10: 100 | H10: 46183.557 | I10: 46183.557
A11: 4647 | B11: Jake Kim | C11: 5587 | D11: Homework Pass | E11: Academic | F11: 0 | G11: 200 | H11: 46183.587 | I11: 46183.589
A12: 4647 | B12: Jake Kim | C12: 2241 | D12: Relaxation Pass | E12: Privilege | F12: 2 | G12: 200 | H12: 46183.587 | I12: 46183.587
A13: 4647 | B13: Jake Kim | C13: 3487 | D13: Preferred Seating Pass | E13: Privilege | F13: 5 | G13: 500 | H13: 46183.588 | I13: 46183.588
A14: 7920 | B14: Alyssa Shin | C14: 6655 | D14: Open-Note Quiz Pass | E14: Academic | F14: 1 | G14: 100 | H14: 46183.588 | I14: 46183.588
A15: 2233 | B15: John | C15: 3313 | D15: +1 Assignment Bonus Token | E15: Academic | F15: 4 | G15: 500 | H15: 46183.65 | I15: 46183.65
A16: 1234 | B16: Test | C16: 6655 | D16: Open-Note Quiz Pass | E16: Academic | F16: 0 | G16: 100 | H16: 46183.653 | I16: 46183.654
... A18: 1234 | B18: Test | C18: 7898 | D18: Participation Recovery Token | E18: Privilege | F18: 0 | G18: 100 | H18: 46183.663 | I18: 46184.647
A19: 7c4e261e | B19: Suha Lee | C19: 7734 | D19: Extra credit 1% | E19: Academic | F19: 0 | G19: 600 | H19: 46184.445 | I19: 46184.446
A20: 5c07fef4 | B20: Tiffany Kim | C20: 7734 | D20: Extra credit 1% | E20: Academic | F20: 0 | G20: 300 | H20: 46184.449 | I20: 46184.45
A21: 6665 | B21: Jinwoo | C21: 7734 | D21: Extra credit 1% | E21: Academic | F21: 1 | G21: 100 | H21: 46184.531 | I21: 46184.531
A22: 5a032611 | B22: Harold Dou | C22: 7734 | D22: Extra credit 1% | E22: Academic | F22: 0 | G22: 1000 | H22: 46184.606 | I22: 46185.382
A23: 1234 | B23: Test | C23: 7734 | D23: Extra credit 1% | E23: Academic | F23: 2 | G23: 400 | H23: 46186.379 | I23: 46186.379

Sheet Jobs
A1: Jobs / Payroll
A3: Card_ID | B3: Student_Name | C3: Job_Title | D3: Salary | E3: Frequency | F3: Active | G3: Last_Paid | H3: Notes
A4: ba353911 | B4: {=IF(A4:A14="","",IFNA(VLOOKUP(A4:A14,Students!A:B,2,FALSE),"Card ID not found"))} -> Dayeon Kang | C4: - | D4: 100 | E4: Weekly | F4: Yes
A5: 5a032611 | B5: Harold Dou | C5: - | D5: 100 | E5: Weekly | F5: Yes
A6: dc04eef4 | B6: Joshua Jung | C6: - | D6: 100 | E6: Weekly | F6: Yes
A7: 7c4e261e | B7: Suha Lee | C7: - | D7: 100 | E7: Weekly | F7: Yes
A8: ba912211 | B8: Daisy Doh | C8: - | D8: 100 | E8: Weekly | F8: Yes
A9: ba0fc5c4 | B9: Junwoo Kang | C9: - | D9: 100 | E9: Weekly | F9: Yes
A10: 5c07fef4 | B10: Tiffany Kim | C10: - | D10: 100 | E10: Weekly | F10: Yes
A11: 1e3e1410 | B11: Junjae Park | C11: - | D11: 100 | E11: Weekly | F11: Yes
A12: babde4c4 | B12: Ashley Guk | C12: - | D12: 100 | E12: Weekly | F12: Yes
A13: ae072910 | B13: Selena Jung | C13: - | D13: 100 | E13: Weekly | F13: Yes
A14: 9a5f2811 | B14: Junyoung Yoo | C14: - | D14: 100 | E14: Weekly | F14: Yes

Sheet Payroll_Log
A1: Jobs / Payroll Log
A3: Payroll_Run_At | B3: Pay_Period_Start | C3: Pay_Period_End | D3: Duration_Days | E3: Card_ID | F3: Student_Name | G3: Job_Title | H3: Salary | I3: Pay_Frequency | J3: Automatic | K3: Status

Sheet Settings
A1: Settings
A3: Setting | B3: Value | C3: Description
A4: Allow_Negative_Balances | B4: FALSE | C4: TRUE allows balances below zero; FALSE denies withdrawals/purchases/fines that exceed balance.
A5: Late_Cutoff_Time | B5: 0.35763889 | C5: Attendance scans after this time are marked Late. Use 24-hour HH:mm format.
A6: On_Time_Bonus | B6: 10 | C6: Optional automatic deposit for on-time attendance. Set 0 to disable.
A7: Late_Bonus | B7: -10 | C7: Optional automatic deposit for late attendance. Set 0 to disable.
A8: Streak_3_Bonus | B8: 50 | C8: Bonus when attendance streak reaches exactly 3.
A9: Streak_5_Bonus | B9: 100 | C9: Bonus when attendance streak reaches exactly 5.
A10: Streak_10_Bonus | B10: 250 | C10: Bonus when attendance streak reaches exactly 10.
A11: Default_Class | B11: Homeroom | C11: Used if Scan!B6 is blank.
A12: Store_Decrease_Inventory | B12: TRUE | C12: TRUE decreases numeric inventory by 1 after successful STORE_PURCHASE.
A13: Payroll_Note | B13: Weekly job salary | C13: Default note used when Run Payroll is clicked.
A14: Google_Doc_ID | B14: 1UeSH3IK6OQRWgm-oVf37S5LqRkZnYkP-k3l4wfQT5SQ | C14: Optional: paste a Google Doc ID to generate attendance reports into a Doc.
A15: Report_To_Doc | B15: TRUE | C15: TRUE sends generated daily attendance report to the Google Doc ID above.
A16: Payroll_Duration_Days | B16: 5
A17: Payroll_Automatic_Day | B17: Friday
A18: Payroll_Automatic_Time | B18: 0.33333333
A19: Timezone | B19: Asia/Seoul

Sheet Reports
A1: Generated Reports
A3: Generated_At | B3: Report_Type | C3: Date | D3: Class_Period | E3: Present | F3: Late | G3: Absent | H3: Details

Sheet Student_Profile
A1: Student Profile
A4: Scan Student Card | B4: 5a032611 | C4: Loaded Harold Dou at 14:47:37 KST | F4: Inventory
F5: Item | G5: Category | H5: Quantity | I5: Total Spent | J5: Last Purchased
A6: Student Name | B6: {=IF($B$4="","",IFNA(XLOOKUP($B$4,Students!$A:$A,Students!$B:$B),"Unknown card"))} -> Harold Dou | C6: Total Deposits | D6: =IF($B$4="","",SUMIFS(Transactions!$F:$F,Transactions!$C:$C,$B$4,Transactions!$E:$E,"DEPOSIT",Transactions!$L:$L,"Success")) -> 35 | F6: =IFERROR(__xludf.DUMMYFUNCTION("IF($B$4="""","""",IFNA(QUERY(SORT(FILTER({Student_Inventory!$D$2:$D38,Student_Inventory!$E$2:$E38,Student_Inventory!$F$2:$F38,Student_Inventory!$G$2:$G38,Student_Inventory!$H$2:$H38},Student_Inventory!$A$2:$A38=$B$4,Student_Inventory!$F$2:$F38>0),5,FALSE)"&",""limit 8"",0),""No inventory found""))"),"No inventory found") -> No inventory found
A7: Grade | B7: {=IF($B$4="","",IFNA(XLOOKUP($B$4,Students!$A:$A,Students!$C:$C),"Unknown card"))} -> 10 | C7: Total Withdrawals | D7: =IF($B$4="","",SUMIFS(Transactions!$F:$F,Transactions!$C:$C,$B$4,Transactions!$E:$E,"WITHDRAW",Transactions!$L:$L,"Success")) -> 0
A8: Homeroom | B8: {=IF($B$4="","",IFNA(XLOOKUP($B$4,Students!$A:$A,Students!$D:$D),""))} -> HS202 | C8: Total Rewards | D8: =IF($B$4="","",SUMIFS(Transactions!$F:$F,Transactions!$C:$C,$B$4,Transactions!$E:$E,"REWARD",Transactions!$L:$L,"Success")) -> 80
A9: Current Balance | B9: {=IF($B$4="","",IFNA(XLOOKUP($B$4,Students!$A:$A,Students!$E:$E),0))} -> 198 | C9: Total Fines | D9: =IF($B$4="","",SUMIFS(Transactions!$F:$F,Transactions!$C:$C,$B$4,Transactions!$E:$E,"FINE",Transactions!$L:$L,"Success")) -> 20
A10: Job Title | B10: {=IF($B$4="","",IFNA(XLOOKUP($B$4,Students!$A:$A,Students!$F:$F),"No job assigned"))} -> - | C10: Store Purchases | D10: =IF($B$4="","",COUNTIFS(Transactions!$C:$C,$B$4,Transactions!$E:$E,"STORE_PURCHASE",Transactions!$L:$L,"Success")) -> 1
A11: Attendance Streak (Days) | B11: {=IF($B$4="","",IFNA(XLOOKUP($B$4,Students!$A:$A,Students!$I:$I),0))} -> 1 | C11: Total Spent | D11: =IF($B$4="","",SUMIFS(Transactions!$F:$F,Transactions!$C:$C,$B$4,Transactions!$E:$E,"STORE_PURCHASE",Transactions!$L:$L,"Success")) -> 1000
A14: Recent Transactions | G14: Purchase History
A15: Date/Time | B15: Type | C15: Amount | D15: Ending Balance | E15: Note | G15: Date/Time | H15: Type | I15: Amount | J15: Balance After | K15: Note
A16: =IFERROR(__xludf.DUMMYFUNCTION("IF($B$4="""","""", IFNA( QUERY( SORT( FILTER( {Transactions!$A$2:$A38,Transactions!$E$2:$E38,Transactions!$F$2:$F38,Transactions!$H$2:$H38,Transactions!$K$2:$K38}, Transactions!$C$2:$C38=$B$4, Transactions!$L$2:$L38=""Success"", "&" NOT(REGEXMATCH(UPPER(Transactions!$E$2:$E38&"" ""&Transactions!$F$2:$F38&"" ""&Transactions!$H$2:$H38&"" ""&Transactions!$K$2:$K38),""REWARD|FINE"")) ), 1,FALSE ), ""limit 10"", 0 ), ""No transactions found"" ) )"),46184.60606481481) -> 46184.606 | B16: =IFERROR(__xludf.DUMMYFUNCTION("""COMPUTED_VALUE"""),"STORE_PURCHASE") -> STORE_PURCHASE | C16: =IFERROR(__xludf.DUMMYFUNCTION("""COMPUTED_VALUE"""),1000.0) -> 1000 | D16: =IFERROR(__xludf.DUMMYFUNCTION("""COMPUTED_VALUE"""),198.0) -> 198 | E16: =IFERROR(__xludf.DUMMYFUNCTION("""COMPUTED_VALUE"""),"Store purchase") -> Store purchase | G16: =IFERROR(__xludf.DUMMYFUNCTION("IF($B$4="""","""",IFNA(QUERY(SORT(FILTER({Transactions!$A$2:$A38,Transactions!$E$2:$E38,Transactions!$F$2:$F38,Transactions!$H$2:$H38,Transactions!$K$2:$K38},Transactions!$C$2:$C38=$B$4,Transactions!$E$2:$E38=""STORE_PURCHASE"",Transactions!$L$2:$L38=""Su"&"ccess""),1,FALSE),""limit 10"",0),""No purchases found""))"),46184.60606481481) -> 46184.606 | H16: =IFERROR(__xludf.DUMMYFUNCTION("""COMPUTED_VALUE"""),"STORE_PURCHASE") -> STORE_PURCHASE | I16: =IFERROR(__xludf.DUMMYFUNCTION("""COMPUTED_VALUE"""),1000.0) -> 1000 | J16: =IFERROR(__xludf.DUMMYFUNCTION("""COMPUTED_VALUE"""),198.0) -> 198 | K16: =IFERROR(__xludf.DUMMYFUNCTION("""COMPUTED_VALUE"""),"Store purchase") -> Store purchase
A17: =IFERROR(__xludf.DUMMYFUNCTION("""COMPUTED_VALUE"""),46178.55496527778) -> 46178.555 | B17: =IFERROR(__xludf.DUMMYFUNCTION("""COMPUTED_VALUE"""),"DEPOSIT") -> DEPOSIT | C17: =IFERROR(__xludf.DUMMYFUNCTION("""COMPUTED_VALUE"""),15.0) -> 15 | D17: =IFERROR(__xludf.DUMMYFUNCTION("""COMPUTED_VALUE"""),65.0) -> 65
A18: =IFERROR(__xludf.DUMMYFUNCTION("""COMPUTED_VALUE"""),46163.469618055555) -> 46163.47 | B18: =IFERROR(__xludf.DUMMYFUNCTION("""COMPUTED_VALUE"""),"DEPOSIT") -> DEPOSIT | C18: =IFERROR(__xludf.DUMMYFUNCTION("""COMPUTED_VALUE"""),20.0) -> 20 | D18: =IFERROR(__xludf.DUMMYFUNCTION("""COMPUTED_VALUE"""),30.0) -> 30
A27: Attendance History | G27: Rewards / Fines
A28: Date/Time | B28: Checkin Time | C28: Status | D28: Note | G28: Date/Time | H28: Type | I28: Amount | J28: Balance After | K28: Note
A29: =IFERROR(__xludf.DUMMYFUNCTION("IF($B$4="""","""",IFNA(QUERY(SORT(FILTER({Attendance_Log!$A:$A,Attendance_Log!$I:$I,Attendance_Log!$H:$H},Attendance_Log!$C:$C=$B$4,Attendance_Log!$M:$M=""Success""),1,FALSE),""limit 10"",0),""No attendance records found""))"),46184.35737268519) -> 46184.357 | B29: =IFERROR(__xludf.DUMMYFUNCTION("""COMPUTED_VALUE"""),0.3573726851864194) -> 0.35737269 | C29: =IFERROR(__xludf.DUMMYFUNCTION("""COMPUTED_VALUE"""),"Present") -> Present | G29: =IFERROR(__xludf.DUMMYFUNCTION("IF($B$4="""","""",IFNA(QUERY(SORT(FILTER({Transactions!$A$2:$A38,Transactions!$E$2:$E38,Transactions!$F$2:$F38,Transactions!$H$2:$H38,Transactions!$K$2:$K38},Transactions!$C$2:$C38=$B$4,REGEXMATCH(Transactions!$E$2:$E38,""REWARD|FINE""),Transactions!$L$2:"&"$L38=""Success""),1,FALSE),""limit 10"",0),""No rewards or fines found""))"),46184.35739583333) -> 46184.357 | H29: =IFERROR(__xludf.DUMMYFUNCTION("""COMPUTED_VALUE"""),"REWARD") -> REWARD | I29: =IFERROR(__xludf.DUMMYFUNCTION("""COMPUTED_VALUE"""),10.0) -> 10 | J29: =IFERROR(__xludf.DUMMYFUNCTION("""COMPUTED_VALUE"""),595.0) -> 595 | K29: =IFERROR(__xludf.DUMMYFUNCTION("""COMPUTED_VALUE"""),"On-time attendance reward") -> On-time attendance reward
A30: =IFERROR(__xludf.DUMMYFUNCTION("""COMPUTED_VALUE"""),46182.35805555555) -> 46182.358 | B30: =IFERROR(__xludf.DUMMYFUNCTION("""COMPUTED_VALUE"""),0.3580555555563478) -> 0.35805556 | C30: =IFERROR(__xludf.DUMMYFUNCTION("""COMPUTED_VALUE"""),"Present") -> Present | G30: =IFERROR(__xludf.DUMMYFUNCTION("""COMPUTED_VALUE"""),46182.358078703706) -> 46182.358 | H30: =IFERROR(__xludf.DUMMYFUNCTION("""COMPUTED_VALUE"""),"REWARD") -> REWARD | I30: =IFERROR(__xludf.DUMMYFUNCTION("""COMPUTED_VALUE"""),10.0) -> 10 | J30: =IFERROR(__xludf.DUMMYFUNCTION("""COMPUTED_VALUE"""),585.0) -> 585 | K30: =IFERROR(__xludf.DUMMYFUNCTION("""COMPUTED_VALUE"""),"On-time attendance reward") -> On-time attendance reward
A31: =IFERROR(__xludf.DUMMYFUNCTION("""COMPUTED_VALUE"""),46181.350648148145) -> 46181.351 | B31: =IFERROR(__xludf.DUMMYFUNCTION("""COMPUTED_VALUE"""),0.3506481481490482) -> 0.35064815 | C31: =IFERROR(__xludf.DUMMYFUNCTION("""COMPUTED_VALUE"""),"Present") -> Present | G31: =IFERROR(__xludf.DUMMYFUNCTION("""COMPUTED_VALUE"""),46181.35068287037) -> 46181.351 | H31: =IFERROR(__xludf.DUMMYFUNCTION("""COMPUTED_VALUE"""),"REWARD") -> REWARD | I31: =IFERROR(__xludf.DUMMYFUNCTION("""COMPUTED_VALUE"""),10.0) -> 10 | J31: =IFERROR(__xludf.DUMMYFUNCTION("""COMPUTED_VALUE"""),575.0) -> 575 | K31: =IFERROR(__xludf.DUMMYFUNCTION("""COMPUTED_VALUE"""),"On-time attendance reward") -> On-time attendance reward
A32: =IFERROR(__xludf.DUMMYFUNCTION("""COMPUTED_VALUE"""),46178.375127314815) -> 46178.375 | B32: =IFERROR(__xludf.DUMMYFUNCTION("""COMPUTED_VALUE"""),0.37512731481547235) -> 0.37512731 | C32: =IFERROR(__xludf.DUMMYFUNCTION("""COMPUTED_VALUE"""),"Late") -> Late | G32: =IFERROR(__xludf.DUMMYFUNCTION("""COMPUTED_VALUE"""),46178.375185185185) -> 46178.375 | H32: =IFERROR(__xludf.DUMMYFUNCTION("""COMPUTED_VALUE"""),"FINE") -> FINE | I32: =IFERROR(__xludf.DUMMYFUNCTION("""COMPUTED_VALUE"""),10.0) -> 10 | J32: =IFERROR(__xludf.DUMMYFUNCTION("""COMPUTED_VALUE"""),50.0) -> 50 | K32: =IFERROR(__xludf.DUMMYFUNCTION("""COMPUTED_VALUE"""),"Late attendance penalty") -> Late attendance penalty
A33: =IFERROR(__xludf.DUMMYFUNCTION("""COMPUTED_VALUE"""),46177.35799768519) -> 46177.358 | B33: =IFERROR(__xludf.DUMMYFUNCTION("""COMPUTED_VALUE"""),0.3579976851870015) -> 0.35799769 | C33: =IFERROR(__xludf.DUMMYFUNCTION("""COMPUTED_VALUE"""),"Present") -> Present | G33: =IFERROR(__xludf.DUMMYFUNCTION("""COMPUTED_VALUE"""),46177.35804398148) -> 46177.358 | H33: =IFERROR(__xludf.DUMMYFUNCTION("""COMPUTED_VALUE"""),"REWARD") -> REWARD | I33: =IFERROR(__xludf.DUMMYFUNCTION("""COMPUTED_VALUE"""),10.0) -> 10 | J33: =IFERROR(__xludf.DUMMYFUNCTION("""COMPUTED_VALUE"""),60.0) -> 60 | K33: =IFERROR(__xludf.DUMMYFUNCTION("""COMPUTED_VALUE"""),"On-time attendance reward") -> On-time attendance reward
A34: =IFERROR(__xludf.DUMMYFUNCTION("""COMPUTED_VALUE"""),46175.3575462963) -> 46175.358 | B34: =IFERROR(__xludf.DUMMYFUNCTION("""COMPUTED_VALUE"""),0.3575462962980964) -> 0.3575463 | C34: =IFERROR(__xludf.DUMMYFUNCTION("""COMPUTED_VALUE"""),"Present") -> Present | G34: =IFERROR(__xludf.DUMMYFUNCTION("""COMPUTED_VALUE"""),46175.357569444444) -> 46175.358 | H34: =IFERROR(__xludf.DUMMYFUNCTION("""COMPUTED_VALUE"""),"REWARD") -> REWARD | I34: =IFERROR(__xludf.DUMMYFUNCTION("""COMPUTED_VALUE"""),10.0) -> 10 | J34: =IFERROR(__xludf.DUMMYFUNCTION("""COMPUTED_VALUE"""),50.0) -> 50 | K34: =IFERROR(__xludf.DUMMYFUNCTION("""COMPUTED_VALUE"""),"On-time attendance reward") -> On-time attendance reward
A35: =IFERROR(__xludf.DUMMYFUNCTION("""COMPUTED_VALUE"""),46174.36565972222) -> 46174.366 | B35: =IFERROR(__xludf.DUMMYFUNCTION("""COMPUTED_VALUE"""),0.3656597222216078) -> 0.36565972 | C35: =IFERROR(__xludf.DUMMYFUNCTION("""COMPUTED_VALUE"""),"Late") -> Late | G35: =IFERROR(__xludf.DUMMYFUNCTION("""COMPUTED_VALUE"""),46174.365694444445) -> 46174.366 | H35: =IFERROR(__xludf.DUMMYFUNCTION("""COMPUTED_VALUE"""),"FINE") -> FINE | I35: =IFERROR(__xludf.DUMMYFUNCTION("""COMPUTED_VALUE"""),10.0) -> 10 | J35: =IFERROR(__xludf.DUMMYFUNCTION("""COMPUTED_VALUE"""),40.0) -> 40 | K35: =IFERROR(__xludf.DUMMYFUNCTION("""COMPUTED_VALUE"""),"Late attendance penalty") -> Late attendance penalty
A36: =IFERROR(__xludf.DUMMYFUNCTION("""COMPUTED_VALUE"""),46168.35590277778) -> 46168.356 | B36: =IFERROR(__xludf.DUMMYFUNCTION("""COMPUTED_VALUE"""),0.35590277777737356) -> 0.35590278 | C36: =IFERROR(__xludf.DUMMYFUNCTION("""COMPUTED_VALUE"""),"Present") -> Present | G36: =IFERROR(__xludf.DUMMYFUNCTION("""COMPUTED_VALUE"""),46168.355937500004) -> 46168.356 | H36: =IFERROR(__xludf.DUMMYFUNCTION("""COMPUTED_VALUE"""),"REWARD") -> REWARD | I36: =IFERROR(__xludf.DUMMYFUNCTION("""COMPUTED_VALUE"""),10.0) -> 10 | J36: =IFERROR(__xludf.DUMMYFUNCTION("""COMPUTED_VALUE"""),50.0) -> 50 | K36: =IFERROR(__xludf.DUMMYFUNCTION("""COMPUTED_VALUE"""),"On-time attendance reward") -> On-time attendance reward
A37: =IFERROR(__xludf.DUMMYFUNCTION("""COMPUTED_VALUE"""),46164.35702546296) -> 46164.357 | B37: =IFERROR(__xludf.DUMMYFUNCTION("""COMPUTED_VALUE"""),0.35702546296306537) -> 0.35702546 | C37: =IFERROR(__xludf.DUMMYFUNCTION("""COMPUTED_VALUE"""),"Present") -> Present | G37: =IFERROR(__xludf.DUMMYFUNCTION("""COMPUTED_VALUE"""),46164.357037037036) -> 46164.357 | H37: =IFERROR(__xludf.DUMMYFUNCTION("""COMPUTED_VALUE"""),"REWARD") -> REWARD | I37: =IFERROR(__xludf.DUMMYFUNCTION("""COMPUTED_VALUE"""),10.0) -> 10 | J37: =IFERROR(__xludf.DUMMYFUNCTION("""COMPUTED_VALUE"""),40.0) -> 40 | K37: =IFERROR(__xludf.DUMMYFUNCTION("""COMPUTED_VALUE"""),"On-time attendance reward") -> On-time attendance reward
A38: =IFERROR(__xludf.DUMMYFUNCTION("""COMPUTED_VALUE"""),46163.35587962963) -> 46163.356 | B38: =IFERROR(__xludf.DUMMYFUNCTION("""COMPUTED_VALUE"""),0.3558796296310902) -> 0.35587963 | C38: =IFERROR(__xludf.DUMMYFUNCTION("""COMPUTED_VALUE"""),"Present") -> Present | G38: =IFERROR(__xludf.DUMMYFUNCTION("""COMPUTED_VALUE"""),46163.35591435185) -> 46163.356 | H38: =IFERROR(__xludf.DUMMYFUNCTION("""COMPUTED_VALUE"""),"REWARD") -> REWARD | I38: =IFERROR(__xludf.DUMMYFUNCTION("""COMPUTED_VALUE"""),10.0) -> 10 | J38: =IFERROR(__xludf.DUMMYFUNCTION("""COMPUTED_VALUE"""),10.0) -> 10 | K38: =IFERROR(__xludf.DUMMYFUNCTION("""COMPUTED_VALUE"""),"On-time attendance reward") -> On-time attendance reward

Sheet Store_Kiosk
A1: Classroom Store Kiosk
A4: 1. Scan Student Card
A6: 2. Store Item ID
A7: 3. Quantity
A9: Result | B9: Lena bought 2 x Homework Pass for 400. New balance: 590.42
A11: Available Store Items
A12: Item ID | B12: Item Name | C12: Price | D12: Inventory | E12: Category | F12: Description
