Workbook

Sheet Store_Kiosk
A1: Classroom Store Kiosk
A4: 1. Scan Student Card
A6: 2. Store Item ID
A7: 3. Quantity
A9: Result | B9: Enter Card ID, Item ID, and Quantity, then press Purchase.
A11: Available Store Items
A12: Item ID | B12: Item Name | D12: Price | E12: Inventory | F12: Category | G12: Description
A13: =IFERROR(__xludf.DUMMYFUNCTION("FILTER( { Imported_Store!A1:A1000, Imported_Store!B1:B1000, IF(ROW(Imported_Store!A1:A1000),"""",), Imported_Store!C1:C1000, Imported_Store!E1:G1000 }, Imported_Store!A1:A1000<>"""", Imported_Store!D1:D1000=""Yes"" )"),7734.0) -> 7734 | B13: =IFERROR(__xludf.DUMMYFUNCTION("""COMPUTED_VALUE"""),"Extra credit 1%") -> Extra credit 1% | D13: =IFERROR(__xludf.DUMMYFUNCTION("""COMPUTED_VALUE"""),100.0) -> 100 | E13: =IFERROR(__xludf.DUMMYFUNCTION("""COMPUTED_VALUE"""),76.0) -> 76 | F13: =IFERROR(__xludf.DUMMYFUNCTION("""COMPUTED_VALUE"""),"Academic") -> Academic | G13: =IFERROR(__xludf.DUMMYFUNCTION("""COMPUTED_VALUE"""),"Get 1% extra credit on an assignment") -> Get 1% extra credit on an assignment

Sheet Student_Profile_Display
A1: Student Profile
A4: Scan Student Card | C4: Scan student card to display profile. | F4: Inventory
F5: Item | G5: Category | H5: Quantity | I5: Total Spent | J5: Last Purchased
A6: Student Name | B6: {=IF($B$4="","",IFNA(XLOOKUP($B$4,Imported_Students!$A:$A,Imported_Students!$B:$B),"Unknown card"))} | C6: Total Deposits | D6: =IF($B$4="","",SUMIFS(Imported_Transactions!$F:$F,Imported_Transactions!$C:$C,$B$4,Imported_Transactions!$E:$E,"DEPOSIT",Imported_Transactions!$L:$L,"Success")) | F6: =IFERROR(__xludf.DUMMYFUNCTION("IF($B$4="""","""",IFNA(QUERY(SORT(FILTER({Imported_Inventory!$D$2:$D70,Imported_Inventory!$E$2:$E70,Imported_Inventory!$F$2:$F70,Imported_Inventory!$G$2:$G70,Imported_Inventory!$H$2:$H70},Imported_Inventory!$A$2:$A70=$B$4,Imported_Inventory!$F$2:$F70>0),5"&",FALSE),""limit 8"",0),""No inventory found""))"),"")
A7: Grade | B7: {=IF($B$4="","",IFNA(XLOOKUP($B$4,Imported_Students!$A:$A,Imported_Students!$C:$C),""))} | C7: Total Withdrawals | D7: =IF($B$4="","",SUMIFS(Imported_Transactions!$F:$F,Imported_Transactions!$C:$C,$B$4,Imported_Transactions!$E:$E,"WITHDRAW",Imported_Transactions!$L:$L,"Success"))
A8: Homeroom | B8: {=IF($B$4="","",IFNA(XLOOKUP($B$4,Imported_Students!$A:$A,Imported_Students!$D:$D),""))} | C8: Total Rewards | D8: =IF($B$4="","",SUMIFS(Imported_Transactions!$F:$F,Imported_Transactions!$C:$C,$B$4,Imported_Transactions!$E:$E,"REWARD",Imported_Transactions!$L:$L,"Success"))
A9: Current Balance | B9: {=IF($B$4="","",IFNA(XLOOKUP($B$4,Imported_Students!$A:$A,Imported_Students!$E:$E),0))} | C9: Total Fines | D9: =IF($B$4="","",SUMIFS(Imported_Transactions!$F:$F,Imported_Transactions!$C:$C,$B$4,Imported_Transactions!$E:$E,"FINE",Imported_Transactions!$L:$L,"Success"))
A10: Job Title | B10: {=IF($B$4="","",IFNA(XLOOKUP($B$4,Imported_Students!$A:$A,Imported_Students!$F:$F),"No job assigned"))} | C10: Store Purchases | D10: =IF($B$4="","",COUNTIFS(Imported_Transactions!$C:$C,$B$4,Imported_Transactions!$E:$E,"STORE_PURCHASE",Imported_Transactions!$L:$L,"Success"))
A11: Attendance Streak (Days) | B11: {=IF($B$4="","",IFNA(XLOOKUP($B$4,Imported_Students!$A:$A,Imported_Students!$G:$G),0))} | C11: Total Spent | D11: =IF($B$4="","",SUMIFS(Imported_Transactions!$F:$F,Imported_Transactions!$C:$C,$B$4,Imported_Transactions!$E:$E,"STORE_PURCHASE",Imported_Transactions!$L:$L,"Success"))
A14: Recent Transactions | G14: Purchase History
A15: Date/Time | B15: Type | C15: Amount | D15: Ending Balance | E15: Note | G15: Date/Time | H15: Type | I15: Amount | J15: Balance After | K15: Note
A16: =IFERROR(__xludf.DUMMYFUNCTION("IF($B$4="""","""", IFNA( QUERY( SORT( FILTER( {Transactions!$A$2:$A70,Transactions!$E$2:$E70,Transactions!$F$2:$F70,Transactions!$H$2:$H70,Transactions!$K$2:$K70}, Transactions!$C$2:$C70=$B$4, Transactions!$L$2:$L70=""Success"", "&" NOT(REGEXMATCH(UPPER(Transactions!$E$2:$E70&"" ""&Transactions!$F$2:$F70&"" ""&Transactions!$H$2:$H70&"" ""&Transactions!$K$2:$K70),""REWARD|FINE"")) ), 1,FALSE ), ""limit 10"", 0 ), ""No transactions found"" ) )"),"") | G16: =IFERROR(__xludf.DUMMYFUNCTION("IF($B$4="""","""",IFNA(QUERY(SORT(FILTER({Transactions!$A$2:$A70,Transactions!$E$2:$E70,Transactions!$F$2:$F70,Transactions!$H$2:$H70,Transactions!$K$2:$K70},Transactions!$C$2:$C70=$B$4,Transactions!$E$2:$E70=""STORE_PURCHASE"",Transactions!$L$2:$L70=""Su"&"ccess""),1,FALSE),""limit 10"",0),""No purchases found""))"),"")
A27: Attendance History | G27: Rewards / Fines
A28: Date/Time | B28: Checkin Time | C28: Status | D28: Note | G28: Date/Time | H28: Type | I28: Amount | J28: Balance After | K28: Note
A29: =IFERROR(__xludf.DUMMYFUNCTION("IF($B$4="""","""",IFNA(QUERY(SORT(FILTER({Imported_Attendance!$A$2:$A70,Imported_Attendance!$I$2:$I70,Imported_Attendance!$H$2:$H70},Imported_Attendance!$C$2:$C70=$B$4),1,FALSE),""limit 10"",0),""No attendance records found""))"),"") | G29: =IFERROR(__xludf.DUMMYFUNCTION("IF($B$4="""","""",IFNA(QUERY(SORT(FILTER({Imported_Transactions!$A$2:$A70,Imported_Transactions!$E$2:$E70,Imported_Transactions!$F$2:$F70,Imported_Transactions!$H$2:$H70,Imported_Transactions!$K$2:$K70},Imported_Transactions!$C$2:$C70=$B$4,REGEXMATCH(Impo"&"rted_Transactions!$E$2:$E70,""REWARD|FINE""),Imported_Transactions!$L$2:$L70=""Success""),1,FALSE),""limit 10"",0),""No rewards or fines found""))"),"")
A39: Stock Portfolio
A40: Ticker | B40: Shares_Owned | C40: Avg_Buy_Price | D40: Total_Cost | E40: Last_Updated
A41: =IFERROR(__xludf.DUMMYFUNCTION("IF($B$4="""","""",IFNA( QUERY( SORT( FILTER( {Imported_Stock_Portfolio!$C$2:$C70,Imported_Stock_Portfolio!$D$2:$D70,Imported_Stock_Portfolio!$E$2:$E70,Imported_Stock_Portfolio!$F$2:$F70,Imported_Stock_Portfolio!$G$2:$G70}, Imported_Stock_Portfolio!$A$2:$A"&"70=$B$4 ), 5,FALSE ), ""limit 10"",0 ), ""No stock holdings found""))"),"")

Sheet Student_Portfolio_Display
A1: Student Stock Portfolio
A3: Scan Student Card | B3: ae072910
A5: Result | B5: Scan a student card, then run Load Stock Portfolio.
A8: Ticker | B8: Shares Owned | C8: Avg Buy Price | D8: Current Price | E8: Market Value | F8: Unrealized Gain/Loss | G8: Last Updated
A9: =IFERROR(__xludf.DUMMYFUNCTION("IF($B$3="""","""",IFNA( QUERY( SORT( FILTER( {Imported_Stock_Portfolio!$C$2:$C73,Imported_Stock_Portfolio!$D$2:$D73,Imported_Stock_Portfolio!$E$2:$E73,Imported_Stock_Portfolio!$G$2:$G73,Imported_Stock_Portfolio!$H$2:$H73,Imported_Stock_Portfolio!$I$2:$I73"&",Imported_Stock_Portfolio!$J$2:$J73}, Imported_Stock_Portfolio!$A$2:$A73=$B$3 ), 5,FALSE ), ""limit 10"",0 ), ""No stock holdings found""))"),"RIDE") -> RIDE | B9: =IFERROR(__xludf.DUMMYFUNCTION("""COMPUTED_VALUE"""),2.0) -> 2 | C9: =IFERROR(__xludf.DUMMYFUNCTION("""COMPUTED_VALUE"""),41.11) -> 41.11 | D9: =IFERROR(__xludf.DUMMYFUNCTION("""COMPUTED_VALUE"""),98.16999999999825) -> 98.17 | E9: =IFERROR(__xludf.DUMMYFUNCTION("""COMPUTED_VALUE"""),196.34) -> 196.34 | F9: =IFERROR(__xludf.DUMMYFUNCTION("""COMPUTED_VALUE"""),114.12) -> 114.12 | G9: =IFERROR(__xludf.DUMMYFUNCTION("""COMPUTED_VALUE"""),46187.706655092596) -> 46187.707
A10: =IFERROR(__xludf.DUMMYFUNCTION("""COMPUTED_VALUE"""),"LOAN") -> LOAN | B10: =IFERROR(__xludf.DUMMYFUNCTION("""COMPUTED_VALUE"""),1.0) -> 1 | C10: =IFERROR(__xludf.DUMMYFUNCTION("""COMPUTED_VALUE"""),58.91) -> 58.91 | D10: =IFERROR(__xludf.DUMMYFUNCTION("""COMPUTED_VALUE"""),76.9900000000016) -> 76.99 | E10: =IFERROR(__xludf.DUMMYFUNCTION("""COMPUTED_VALUE"""),76.99) -> 76.99 | F10: =IFERROR(__xludf.DUMMYFUNCTION("""COMPUTED_VALUE"""),18.08) -> 18.08 | G10: =IFERROR(__xludf.DUMMYFUNCTION("""COMPUTED_VALUE"""),46187.706655092596) -> 46187.707

Sheet Imported_Students
A1: =IFERROR(__xludf.DUMMYFUNCTION("IMPORTRANGE(""https://docs.google.com/spreadsheets/d/1xmGsP2eOXdfhJ9DjzCOVFJKoZ2DuuwRb_dbNg1M77M8/edit?gid=138364344#gid=138364344"",""Students!A:J"")"),"Students / Card Registry") -> Students / Card Registry
A3: =IFERROR(__xludf.DUMMYFUNCTION("""COMPUTED_VALUE"""),"Card_ID") -> Card_ID | B3: =IFERROR(__xludf.DUMMYFUNCTION("""COMPUTED_VALUE"""),"Student_Name") -> Student_Name | C3: =IFERROR(__xludf.DUMMYFUNCTION("""COMPUTED_VALUE"""),"Grade") -> Grade | D3: =IFERROR(__xludf.DUMMYFUNCTION("""COMPUTED_VALUE"""),"Homeroom") -> Homeroom | E3: =IFERROR(__xludf.DUMMYFUNCTION("""COMPUTED_VALUE"""),"Balance") -> Balance | F3: =IFERROR(__xludf.DUMMYFUNCTION("""COMPUTED_VALUE"""),"Job_Title") -> Job_Title | G3: =IFERROR(__xludf.DUMMYFUNCTION("""COMPUTED_VALUE"""),"Active") -> Active | H3: =IFERROR(__xludf.DUMMYFUNCTION("""COMPUTED_VALUE"""),"Last_Updated") -> Last_Updated | I3: =IFERROR(__xludf.DUMMYFUNCTION("""COMPUTED_VALUE"""),"Attendance_Streak") -> Attendance_Streak | J3: =IFERROR(__xludf.DUMMYFUNCTION("""COMPUTED_VALUE"""),"Last_Attendance_Date") -> Last_Attendance_Date
A4: =IFERROR(__xludf.DUMMYFUNCTION("""COMPUTED_VALUE"""),"ba353911") -> ba353911 | B4: =IFERROR(__xludf.DUMMYFUNCTION("""COMPUTED_VALUE"""),"Dayeon Kang") -> Dayeon Kang | C4: =IFERROR(__xludf.DUMMYFUNCTION("""COMPUTED_VALUE"""),10.0) -> 10 | D4: =IFERROR(__xludf.DUMMYFUNCTION("""COMPUTED_VALUE"""),"HS202") -> HS202 | E4: =IFERROR(__xludf.DUMMYFUNCTION("""COMPUTED_VALUE"""),341.98) -> 341.98 | F4: =IFERROR(__xludf.DUMMYFUNCTION("""COMPUTED_VALUE"""),"-") -> - | G4: =IFERROR(__xludf.DUMMYFUNCTION("""COMPUTED_VALUE"""),"Yes") -> Yes | H4: =IFERROR(__xludf.DUMMYFUNCTION("""COMPUTED_VALUE"""),46184.3566087963) -> 46184.357 | I4: =IFERROR(__xludf.DUMMYFUNCTION("""COMPUTED_VALUE"""),4.0) -> 4 | J4: =IFERROR(__xludf.DUMMYFUNCTION("""COMPUTED_VALUE"""),46184.0) -> 46184
A5: =IFERROR(__xludf.DUMMYFUNCTION("""COMPUTED_VALUE"""),"dc04eef4") -> dc04eef4 | B5: =IFERROR(__xludf.DUMMYFUNCTION("""COMPUTED_VALUE"""),"Joshua Jung") -> Joshua Jung | C5: =IFERROR(__xludf.DUMMYFUNCTION("""COMPUTED_VALUE"""),10.0) -> 10 | D5: =IFERROR(__xludf.DUMMYFUNCTION("""COMPUTED_VALUE"""),"HS202") -> HS202 | E5: =IFERROR(__xludf.DUMMYFUNCTION("""COMPUTED_VALUE"""),234.86) -> 234.86 | F5: =IFERROR(__xludf.DUMMYFUNCTION("""COMPUTED_VALUE"""),"-") -> - | G5: =IFERROR(__xludf.DUMMYFUNCTION("""COMPUTED_VALUE"""),"Yes") -> Yes | H5: =IFERROR(__xludf.DUMMYFUNCTION("""COMPUTED_VALUE"""),46185.35445601852) -> 46185.354 | I5: =IFERROR(__xludf.DUMMYFUNCTION("""COMPUTED_VALUE"""),5.0) -> 5 | J5: =IFERROR(__xludf.DUMMYFUNCTION("""COMPUTED_VALUE"""),46185.0) -> 46185
A6: =IFERROR(__xludf.DUMMYFUNCTION("""COMPUTED_VALUE"""),"5a032611") -> 5a032611 | B6: =IFERROR(__xludf.DUMMYFUNCTION("""COMPUTED_VALUE"""),"Harold Dou") -> Harold Dou | C6: =IFERROR(__xludf.DUMMYFUNCTION("""COMPUTED_VALUE"""),10.0) -> 10 | D6: =IFERROR(__xludf.DUMMYFUNCTION("""COMPUTED_VALUE"""),"HS202") -> HS202 | E6: =IFERROR(__xludf.DUMMYFUNCTION("""COMPUTED_VALUE"""),198.0) -> 198 | F6: =IFERROR(__xludf.DUMMYFUNCTION("""COMPUTED_VALUE"""),"-") -> - | G6: =IFERROR(__xludf.DUMMYFUNCTION("""COMPUTED_VALUE"""),"Yes") -> Yes | H6: =IFERROR(__xludf.DUMMYFUNCTION("""COMPUTED_VALUE"""),46184.60606481481) -> 46184.606 | I6: =IFERROR(__xludf.DUMMYFUNCTION("""COMPUTED_VALUE"""),1.0) -> 1 | J6: =IFERROR(__xludf.DUMMYFUNCTION("""COMPUTED_VALUE"""),46184.0) -> 46184
A7: =IFERROR(__xludf.DUMMYFUNCTION("""COMPUTED_VALUE"""),"7c4e261e") -> 7c4e261e | B7: =IFERROR(__xludf.DUMMYFUNCTION("""COMPUTED_VALUE"""),"Suha Lee") -> Suha Lee | C7: =IFERROR(__xludf.DUMMYFUNCTION("""COMPUTED_VALUE"""),10.0) -> 10 | D7: =IFERROR(__xludf.DUMMYFUNCTION("""COMPUTED_VALUE"""),"HS202") -> HS202 | E7: =IFERROR(__xludf.DUMMYFUNCTION("""COMPUTED_VALUE"""),49.83) -> 49.83 | F7: =IFERROR(__xludf.DUMMYFUNCTION("""COMPUTED_VALUE"""),"-") -> - | G7: =IFERROR(__xludf.DUMMYFUNCTION("""COMPUTED_VALUE"""),"Yes") -> Yes | H7: =IFERROR(__xludf.DUMMYFUNCTION("""COMPUTED_VALUE"""),46185.35123842592) -> 46185.351 | I7: =IFERROR(__xludf.DUMMYFUNCTION("""COMPUTED_VALUE"""),4.0) -> 4 | J7: =IFERROR(__xludf.DUMMYFUNCTION("""COMPUTED_VALUE"""),46185.0) -> 46185
A8: =IFERROR(__xludf.DUMMYFUNCTION("""COMPUTED_VALUE"""),"ba0fc5c4") -> ba0fc5c4 | B8: =IFERROR(__xludf.DUMMYFUNCTION("""COMPUTED_VALUE"""),"Junwoo Kang") -> Junwoo Kang | C8: =IFERROR(__xludf.DUMMYFUNCTION("""COMPUTED_VALUE"""),10.0) -> 10 | D8: =IFERROR(__xludf.DUMMYFUNCTION("""COMPUTED_VALUE"""),"HS202") -> HS202 | E8: =IFERROR(__xludf.DUMMYFUNCTION("""COMPUTED_VALUE"""),4.19) -> 4.19 | F8: =IFERROR(__xludf.DUMMYFUNCTION("""COMPUTED_VALUE"""),"-") -> - | G8: =IFERROR(__xludf.DUMMYFUNCTION("""COMPUTED_VALUE"""),"Yes") -> Yes | H8: =IFERROR(__xludf.DUMMYFUNCTION("""COMPUTED_VALUE"""),46184.50125) -> 46184.501 | I8: =IFERROR(__xludf.DUMMYFUNCTION("""COMPUTED_VALUE"""),0.0) -> 0 | J8: =IFERROR(__xludf.DUMMYFUNCTION("""COMPUTED_VALUE"""),46181.0) -> 46181
A9: =IFERROR(__xludf.DUMMYFUNCTION("""COMPUTED_VALUE"""),"ba912211") -> ba912211 | B9: =IFERROR(__xludf.DUMMYFUNCTION("""COMPUTED_VALUE"""),"Daisy Doh") -> Daisy Doh | C9: =IFERROR(__xludf.DUMMYFUNCTION("""COMPUTED_VALUE"""),10.0) -> 10 | D9: =IFERROR(__xludf.DUMMYFUNCTION("""COMPUTED_VALUE"""),"HS202") -> HS202 | E9: =IFERROR(__xludf.DUMMYFUNCTION("""COMPUTED_VALUE"""),483.88) -> 483.88 | F9: =IFERROR(__xludf.DUMMYFUNCTION("""COMPUTED_VALUE"""),"-") -> - | G9: =IFERROR(__xludf.DUMMYFUNCTION("""COMPUTED_VALUE"""),"Yes") -> Yes | H9: =IFERROR(__xludf.DUMMYFUNCTION("""COMPUTED_VALUE"""),46185.34641203703) -> 46185.346 | I9: =IFERROR(__xludf.DUMMYFUNCTION("""COMPUTED_VALUE"""),5.0) -> 5 | J9: =IFERROR(__xludf.DUMMYFUNCTION("""COMPUTED_VALUE"""),46185.0) -> 46185
A10: =IFERROR(__xludf.DUMMYFUNCTION("""COMPUTED_VALUE"""),"5c07fef4") -> 5c07fef4 | B10: =IFERROR(__xludf.DUMMYFUNCTION("""COMPUTED_VALUE"""),"Tiffany Kim") -> Tiffany Kim | C10: =IFERROR(__xludf.DUMMYFUNCTION("""COMPUTED_VALUE"""),10.0) -> 10 | D10: =IFERROR(__xludf.DUMMYFUNCTION("""COMPUTED_VALUE"""),"HS202") -> HS202 | E10: =IFERROR(__xludf.DUMMYFUNCTION("""COMPUTED_VALUE"""),430.0) -> 430 | F10: =IFERROR(__xludf.DUMMYFUNCTION("""COMPUTED_VALUE"""),"-") -> - | G10: =IFERROR(__xludf.DUMMYFUNCTION("""COMPUTED_VALUE"""),"Yes") -> Yes | H10: =IFERROR(__xludf.DUMMYFUNCTION("""COMPUTED_VALUE"""),46185.346180555556) -> 46185.346 | I10: =IFERROR(__xludf.DUMMYFUNCTION("""COMPUTED_VALUE"""),5.0) -> 5 | J10: =IFERROR(__xludf.DUMMYFUNCTION("""COMPUTED_VALUE"""),46185.0) -> 46185
A11: =IFERROR(__xludf.DUMMYFUNCTION("""COMPUTED_VALUE"""),"babde4c4") -> babde4c4 | B11: =IFERROR(__xludf.DUMMYFUNCTION("""COMPUTED_VALUE"""),"Ashley Guk") -> Ashley Guk | C11: =IFERROR(__xludf.DUMMYFUNCTION("""COMPUTED_VALUE"""),10.0) -> 10 | D11: =IFERROR(__xludf.DUMMYFUNCTION("""COMPUTED_VALUE"""),"HS202") -> HS202 | E11: =IFERROR(__xludf.DUMMYFUNCTION("""COMPUTED_VALUE"""),616.0) -> 616 | F11: =IFERROR(__xludf.DUMMYFUNCTION("""COMPUTED_VALUE"""),"-") -> - | G11: =IFERROR(__xludf.DUMMYFUNCTION("""COMPUTED_VALUE"""),"Yes") -> Yes | H11: =IFERROR(__xludf.DUMMYFUNCTION("""COMPUTED_VALUE"""),46184.35596064815) -> 46184.356 | I11: =IFERROR(__xludf.DUMMYFUNCTION("""COMPUTED_VALUE"""),1.0) -> 1 | J11: =IFERROR(__xludf.DUMMYFUNCTION("""COMPUTED_VALUE"""),46184.0) -> 46184
A12: =IFERROR(__xludf.DUMMYFUNCTION("""COMPUTED_VALUE"""),"ae072910") -> ae072910 | B12: =IFERROR(__xludf.DUMMYFUNCTION("""COMPUTED_VALUE"""),"Selena Jung") -> Selena Jung | C12: =IFERROR(__xludf.DUMMYFUNCTION("""COMPUTED_VALUE"""),10.0) -> 10 | D12: =IFERROR(__xludf.DUMMYFUNCTION("""COMPUTED_VALUE"""),"HS202") -> HS202 | E12: =IFERROR(__xludf.DUMMYFUNCTION("""COMPUTED_VALUE"""),353.79) -> 353.79 | F12: =IFERROR(__xludf.DUMMYFUNCTION("""COMPUTED_VALUE"""),"-") -> - | G12: =IFERROR(__xludf.DUMMYFUNCTION("""COMPUTED_VALUE"""),"Yes") -> Yes | H12: =IFERROR(__xludf.DUMMYFUNCTION("""COMPUTED_VALUE"""),46184.351122685184) -> 46184.351 | I12: =IFERROR(__xludf.DUMMYFUNCTION("""COMPUTED_VALUE"""),4.0) -> 4 | J12: =IFERROR(__xludf.DUMMYFUNCTION("""COMPUTED_VALUE"""),46184.0) -> 46184
A13: =IFERROR(__xludf.DUMMYFUNCTION("""COMPUTED_VALUE"""),"1e3e1410") -> 1e3e1410 | B13: =IFERROR(__xludf.DUMMYFUNCTION("""COMPUTED_VALUE"""),"Junjae Park") -> Junjae Park | C13: =IFERROR(__xludf.DUMMYFUNCTION("""COMPUTED_VALUE"""),10.0) -> 10 | D13: =IFERROR(__xludf.DUMMYFUNCTION("""COMPUTED_VALUE"""),"HS202") -> HS202 | E13: =IFERROR(__xludf.DUMMYFUNCTION("""COMPUTED_VALUE"""),27.98) -> 27.98 | F13: =IFERROR(__xludf.DUMMYFUNCTION("""COMPUTED_VALUE"""),"-") -> - | G13: =IFERROR(__xludf.DUMMYFUNCTION("""COMPUTED_VALUE"""),"Yes") -> Yes | H13: =IFERROR(__xludf.DUMMYFUNCTION("""COMPUTED_VALUE"""),46185.64902777778) -> 46185.649 | I13: =IFERROR(__xludf.DUMMYFUNCTION("""COMPUTED_VALUE"""),5.0) -> 5 | J13: =IFERROR(__xludf.DUMMYFUNCTION("""COMPUTED_VALUE"""),46185.0) -> 46185
A14: =IFERROR(__xludf.DUMMYFUNCTION("""COMPUTED_VALUE"""),"9a5f2811") -> 9a5f2811 | B14: =IFERROR(__xludf.DUMMYFUNCTION("""COMPUTED_VALUE"""),"Junyoung Yoo") -> Junyoung Yoo | C14: =IFERROR(__xludf.DUMMYFUNCTION("""COMPUTED_VALUE"""),10.0) -> 10 | D14: =IFERROR(__xludf.DUMMYFUNCTION("""COMPUTED_VALUE"""),"HS202") -> HS202 | E14: =IFERROR(__xludf.DUMMYFUNCTION("""COMPUTED_VALUE"""),46.86) -> 46.86 | F14: =IFERROR(__xludf.DUMMYFUNCTION("""COMPUTED_VALUE"""),"-") -> - | G14: =IFERROR(__xludf.DUMMYFUNCTION("""COMPUTED_VALUE"""),"Yes") -> Yes | H14: =IFERROR(__xludf.DUMMYFUNCTION("""COMPUTED_VALUE"""),46184.467881944445) -> 46184.468 | I14: =IFERROR(__xludf.DUMMYFUNCTION("""COMPUTED_VALUE"""),0.0) -> 0 | J14: =IFERROR(__xludf.DUMMYFUNCTION("""COMPUTED_VALUE"""),46183.0) -> 46183
A15: =IFERROR(__xludf.DUMMYFUNCTION("""COMPUTED_VALUE"""),1321.0) -> 1321 | B15: =IFERROR(__xludf.DUMMYFUNCTION("""COMPUTED_VALUE"""),"Ahin") -> Ahin | C15: =IFERROR(__xludf.DUMMYFUNCTION("""COMPUTED_VALUE"""),7.0) -> 7 | D15: =IFERROR(__xludf.DUMMYFUNCTION("""COMPUTED_VALUE"""),"HS202") -> HS202 | E15: =IFERROR(__xludf.DUMMYFUNCTION("""COMPUTED_VALUE"""),743.61) -> 743.61 | F15: =IFERROR(__xludf.DUMMYFUNCTION("""COMPUTED_VALUE"""),"-") -> - | G15: =IFERROR(__xludf.DUMMYFUNCTION("""COMPUTED_VALUE"""),"Yes") -> Yes | H15: =IFERROR(__xludf.DUMMYFUNCTION("""COMPUTED_VALUE"""),46186.43682870371) -> 46186.437
A16: =IFERROR(__xludf.DUMMYFUNCTION("""COMPUTED_VALUE"""),4673.0) -> 4673 | B16: =IFERROR(__xludf.DUMMYFUNCTION("""COMPUTED_VALUE"""),"Ellie") -> Ellie | C16: =IFERROR(__xludf.DUMMYFUNCTION("""COMPUTED_VALUE"""),7.0) -> 7 | D16: =IFERROR(__xludf.DUMMYFUNCTION("""COMPUTED_VALUE"""),"HS203") -> HS203 | E16: =IFERROR(__xludf.DUMMYFUNCTION("""COMPUTED_VALUE"""),8764.1) -> 8764.1 | F16: =IFERROR(__xludf.DUMMYFUNCTION("""COMPUTED_VALUE"""),"-") -> - | G16: =IFERROR(__xludf.DUMMYFUNCTION("""COMPUTED_VALUE"""),"Yes") -> Yes | H16: =IFERROR(__xludf.DUMMYFUNCTION("""COMPUTED_VALUE"""),46185.53475694444) -> 46185.535
A17: =IFERROR(__xludf.DUMMYFUNCTION("""COMPUTED_VALUE"""),2217.0) -> 2217 | B17: =IFERROR(__xludf.DUMMYFUNCTION("""COMPUTED_VALUE"""),"DK") -> DK | C17: =IFERROR(__xludf.DUMMYFUNCTION("""COMPUTED_VALUE"""),7.0) -> 7 | D17: =IFERROR(__xludf.DUMMYFUNCTION("""COMPUTED_VALUE"""),"HS204") -> HS204 | E17: =IFERROR(__xludf.DUMMYFUNCTION("""COMPUTED_VALUE"""),8404.61) -> 8404.61 | F17: =IFERROR(__xludf.DUMMYFUNCTION("""COMPUTED_VALUE"""),"-") -> - | G17: =IFERROR(__xludf.DUMMYFUNCTION("""COMPUTED_VALUE"""),"Yes") -> Yes | H17: =IFERROR(__xludf.DUMMYFUNCTION("""COMPUTED_VALUE"""),46185.67994212963) -> 46185.68
A18: =IFERROR(__xludf.DUMMYFUNCTION("""COMPUTED_VALUE"""),1978.0) -> 1978 | B18: =IFERROR(__xludf.DUMMYFUNCTION("""COMPUTED_VALUE"""),"Hannah") -> Hannah | C18: =IFERROR(__xludf.DUMMYFUNCTION("""COMPUTED_VALUE"""),7.0) -> 7 | D18: =IFERROR(__xludf.DUMMYFUNCTION("""COMPUTED_VALUE"""),"HS205") -> HS205 | E18: =IFERROR(__xludf.DUMMYFUNCTION("""COMPUTED_VALUE"""),10028.2) -> 10028.2 | F18: =IFERROR(__xludf.DUMMYFUNCTION("""COMPUTED_VALUE"""),"-") -> - | G18: =IFERROR(__xludf.DUMMYFUNCTION("""COMPUTED_VALUE"""),"Yes") -> Yes | H18: =IFERROR(__xludf.DUMMYFUNCTION("""COMPUTED_VALUE"""),46178.54225694444) -> 46178.542
A19: =IFERROR(__xludf.DUMMYFUNCTION("""COMPUTED_VALUE"""),1876.0) -> 1876 | B19: =IFERROR(__xludf.DUMMYFUNCTION("""COMPUTED_VALUE"""),"Lena") -> Lena | C19: =IFERROR(__xludf.DUMMYFUNCTION("""COMPUTED_VALUE"""),7.0) -> 7 | D19: =IFERROR(__xludf.DUMMYFUNCTION("""COMPUTED_VALUE"""),"HS206") -> HS206 | E19: =IFERROR(__xludf.DUMMYFUNCTION("""COMPUTED_VALUE"""),311.09) -> 311.09 | F19: =IFERROR(__xludf.DUMMYFUNCTION("""COMPUTED_VALUE"""),"-") -> - | G19: =IFERROR(__xludf.DUMMYFUNCTION("""COMPUTED_VALUE"""),"Yes") -> Yes | H19: =IFERROR(__xludf.DUMMYFUNCTION("""COMPUTED_VALUE"""),46185.57885416667) -> 46185.579
A20: =IFERROR(__xludf.DUMMYFUNCTION("""COMPUTED_VALUE"""),8765.0) -> 8765 | B20: =IFERROR(__xludf.DUMMYFUNCTION("""COMPUTED_VALUE"""),"Minjun") -> Minjun | C20: =IFERROR(__xludf.DUMMYFUNCTION("""COMPUTED_VALUE"""),7.0) -> 7 | D20: =IFERROR(__xludf.DUMMYFUNCTION("""COMPUTED_VALUE"""),"HS207") -> HS207 | E20: =IFERROR(__xludf.DUMMYFUNCTION("""COMPUTED_VALUE"""),1135.58) -> 1135.58 | F20: =IFERROR(__xludf.DUMMYFUNCTION("""COMPUTED_VALUE"""),"-") -> - | G20: =IFERROR(__xludf.DUMMYFUNCTION("""COMPUTED_VALUE"""),"Yes") -> Yes | H20: =IFERROR(__xludf.DUMMYFUNCTION("""COMPUTED_VALUE"""),46187.40190972222) -> 46187.402
A21: =IFERROR(__xludf.DUMMYFUNCTION("""COMPUTED_VALUE"""),9887.0) -> 9887 | B21: =IFERROR(__xludf.DUMMYFUNCTION("""COMPUTED_VALUE"""),"Ruby") -> Ruby | C21: =IFERROR(__xludf.DUMMYFUNCTION("""COMPUTED_VALUE"""),7.0) -> 7 | D21: =IFERROR(__xludf.DUMMYFUNCTION("""COMPUTED_VALUE"""),"HS208") -> HS208 | E21: =IFERROR(__xludf.DUMMYFUNCTION("""COMPUTED_VALUE"""),1827.26) -> 1827.26 | F21: =IFERROR(__xludf.DUMMYFUNCTION("""COMPUTED_VALUE"""),"-") -> - | G21: =IFERROR(__xludf.DUMMYFUNCTION("""COMPUTED_VALUE"""),"Yes") -> Yes | H21: =IFERROR(__xludf.DUMMYFUNCTION("""COMPUTED_VALUE"""),46185.523518518516) -> 46185.524
A22: =IFERROR(__xludf.DUMMYFUNCTION("""COMPUTED_VALUE"""),7765.0) -> 7765 | B22: =IFERROR(__xludf.DUMMYFUNCTION("""COMPUTED_VALUE"""),"Yeonju") -> Yeonju | C22: =IFERROR(__xludf.DUMMYFUNCTION("""COMPUTED_VALUE"""),7.0) -> 7 | D22: =IFERROR(__xludf.DUMMYFUNCTION("""COMPUTED_VALUE"""),"HS209") -> HS209 | E22: =IFERROR(__xludf.DUMMYFUNCTION("""COMPUTED_VALUE"""),5263.92) -> 5263.92 | F22: =IFERROR(__xludf.DUMMYFUNCTION("""COMPUTED_VALUE"""),"-") -> - | G22: =IFERROR(__xludf.DUMMYFUNCTION("""COMPUTED_VALUE"""),"Yes") -> Yes | H22: =IFERROR(__xludf.DUMMYFUNCTION("""COMPUTED_VALUE"""),46185.44773148148) -> 46185.448
A23: =IFERROR(__xludf.DUMMYFUNCTION("""COMPUTED_VALUE"""),6665.0) -> 6665 | B23: =IFERROR(__xludf.DUMMYFUNCTION("""COMPUTED_VALUE"""),"Jinwoo") -> Jinwoo | C23: =IFERROR(__xludf.DUMMYFUNCTION("""COMPUTED_VALUE"""),7.0) -> 7 | D23: =IFERROR(__xludf.DUMMYFUNCTION("""COMPUTED_VALUE"""),"HS210") -> HS210 | E23: =IFERROR(__xludf.DUMMYFUNCTION("""COMPUTED_VALUE"""),1553.49) -> 1553.49 | F23: =IFERROR(__xludf.DUMMYFUNCTION("""COMPUTED_VALUE"""),"-") -> - | G23: =IFERROR(__xludf.DUMMYFUNCTION("""COMPUTED_VALUE"""),"Yes") -> Yes | H23: =IFERROR(__xludf.DUMMYFUNCTION("""COMPUTED_VALUE"""),46185.53681712963) -> 46185.537
A24: =IFERROR(__xludf.DUMMYFUNCTION("""COMPUTED_VALUE"""),8989.0) -> 8989 | B24: =IFERROR(__xludf.DUMMYFUNCTION("""COMPUTED_VALUE"""),"Oakley") -> Oakley | C24: =IFERROR(__xludf.DUMMYFUNCTION("""COMPUTED_VALUE"""),7.0) -> 7 | D24: =IFERROR(__xludf.DUMMYFUNCTION("""COMPUTED_VALUE"""),"HS211") -> HS211 | E24: =IFERROR(__xludf.DUMMYFUNCTION("""COMPUTED_VALUE"""),7002.67) -> 7002.67 | F24: =IFERROR(__xludf.DUMMYFUNCTION("""COMPUTED_VALUE"""),"-") -> - | G24: =IFERROR(__xludf.DUMMYFUNCTION("""COMPUTED_VALUE"""),"Yes") -> Yes | H24: =IFERROR(__xludf.DUMMYFUNCTION("""COMPUTED_VALUE"""),46185.5353125) -> 46185.535
A25: =IFERROR(__xludf.DUMMYFUNCTION("""COMPUTED_VALUE"""),1234.0) -> 1234 | B25: =IFERROR(__xludf.DUMMYFUNCTION("""COMPUTED_VALUE"""),"Test") -> Test | C25: =IFERROR(__xludf.DUMMYFUNCTION("""COMPUTED_VALUE"""),11.0) -> 11 | E25: =IFERROR(__xludf.DUMMYFUNCTION("""COMPUTED_VALUE"""),95.34) -> 95.34 | F25: =IFERROR(__xludf.DUMMYFUNCTION("""COMPUTED_VALUE"""),"-") -> - | G25: =IFERROR(__xludf.DUMMYFUNCTION("""COMPUTED_VALUE"""),"Yes") -> Yes | H25: =IFERROR(__xludf.DUMMYFUNCTION("""COMPUTED_VALUE"""),46186.699421296296) -> 46186.699
A26: =IFERROR(__xludf.DUMMYFUNCTION("""COMPUTED_VALUE"""),8244.0) -> 8244 | B26: =IFERROR(__xludf.DUMMYFUNCTION("""COMPUTED_VALUE"""),"Alexis Parisee") -> Alexis Parisee | C26: =IFERROR(__xludf.DUMMYFUNCTION("""COMPUTED_VALUE"""),11.0) -> 11 | D26: =IFERROR(__xludf.DUMMYFUNCTION("""COMPUTED_VALUE"""),"HS203") -> HS203 | E26: =IFERROR(__xludf.DUMMYFUNCTION("""COMPUTED_VALUE"""),1000.0) -> 1000 | F26: =IFERROR(__xludf.DUMMYFUNCTION("""COMPUTED_VALUE"""),"-") -> - | G26: =IFERROR(__xludf.DUMMYFUNCTION("""COMPUTED_VALUE"""),"Yes") -> Yes
A27: =IFERROR(__xludf.DUMMYFUNCTION("""COMPUTED_VALUE"""),3846.0) -> 3846 | B27: =IFERROR(__xludf.DUMMYFUNCTION("""COMPUTED_VALUE"""),"Jace Kim") -> Jace Kim | C27: =IFERROR(__xludf.DUMMYFUNCTION("""COMPUTED_VALUE"""),11.0) -> 11 | D27: =IFERROR(__xludf.DUMMYFUNCTION("""COMPUTED_VALUE"""),"HS204") -> HS204 | E27: =IFERROR(__xludf.DUMMYFUNCTION("""COMPUTED_VALUE"""),1893.12) -> 1893.12 | F27: =IFERROR(__xludf.DUMMYFUNCTION("""COMPUTED_VALUE"""),"-") -> - | G27: =IFERROR(__xludf.DUMMYFUNCTION("""COMPUTED_VALUE"""),"Yes") -> Yes | H27: =IFERROR(__xludf.DUMMYFUNCTION("""COMPUTED_VALUE"""),46184.38476851852) -> 46184.385
A28: =IFERROR(__xludf.DUMMYFUNCTION("""COMPUTED_VALUE"""),2659.0) -> 2659 | B28: =IFERROR(__xludf.DUMMYFUNCTION("""COMPUTED_VALUE"""),"Jin Park") -> Jin Park | C28: =IFERROR(__xludf.DUMMYFUNCTION("""COMPUTED_VALUE"""),11.0) -> 11 | D28: =IFERROR(__xludf.DUMMYFUNCTION("""COMPUTED_VALUE"""),"HS205") -> HS205 | E28: =IFERROR(__xludf.DUMMYFUNCTION("""COMPUTED_VALUE"""),3.56) -> 3.56 | F28: =IFERROR(__xludf.DUMMYFUNCTION("""COMPUTED_VALUE"""),"-") -> - | G28: =IFERROR(__xludf.DUMMYFUNCTION("""COMPUTED_VALUE"""),"Yes") -> Yes | H28: =IFERROR(__xludf.DUMMYFUNCTION("""COMPUTED_VALUE"""),46183.57168981482) -> 46183.572
A29: =IFERROR(__xludf.DUMMYFUNCTION("""COMPUTED_VALUE"""),7302.0) -> 7302 | B29: =IFERROR(__xludf.DUMMYFUNCTION("""COMPUTED_VALUE"""),"Claire Yang") -> Claire Yang | C29: =IFERROR(__xludf.DUMMYFUNCTION("""COMPUTED_VALUE"""),11.0) -> 11 | D29: =IFERROR(__xludf.DUMMYFUNCTION("""COMPUTED_VALUE"""),"HS206") -> HS206 | E29: =IFERROR(__xludf.DUMMYFUNCTION("""COMPUTED_VALUE"""),43.05) -> 43.05 | F29: =IFERROR(__xludf.DUMMYFUNCTION("""COMPUTED_VALUE"""),"-") -> - | G29: =IFERROR(__xludf.DUMMYFUNCTION("""COMPUTED_VALUE"""),"Yes") -> Yes | H29: =IFERROR(__xludf.DUMMYFUNCTION("""COMPUTED_VALUE"""),46183.57829861111) -> 46183.578
A30: =IFERROR(__xludf.DUMMYFUNCTION("""COMPUTED_VALUE"""),5420.0) -> 5420 | B30: =IFERROR(__xludf.DUMMYFUNCTION("""COMPUTED_VALUE"""),"Daniel Park") -> Daniel Park | C30: =IFERROR(__xludf.DUMMYFUNCTION("""COMPUTED_VALUE"""),11.0) -> 11 | D30: =IFERROR(__xludf.DUMMYFUNCTION("""COMPUTED_VALUE"""),"HS207") -> HS207 | E30: =IFERROR(__xludf.DUMMYFUNCTION("""COMPUTED_VALUE"""),5.81) -> 5.81 | F30: =IFERROR(__xludf.DUMMYFUNCTION("""COMPUTED_VALUE"""),"-") -> - | G30: =IFERROR(__xludf.DUMMYFUNCTION("""COMPUTED_VALUE"""),"Yes") -> Yes | H30: =IFERROR(__xludf.DUMMYFUNCTION("""COMPUTED_VALUE"""),46185.623460648145) -> 46185.623
A31: =IFERROR(__xludf.DUMMYFUNCTION("""COMPUTED_VALUE"""),4098.0) -> 4098 | B31: =IFERROR(__xludf.DUMMYFUNCTION("""COMPUTED_VALUE"""),"Anthony Ahn") -> Anthony Ahn | C31: =IFERROR(__xludf.DUMMYFUNCTION("""COMPUTED_VALUE"""),11.0) -> 11 | D31: =IFERROR(__xludf.DUMMYFUNCTION("""COMPUTED_VALUE"""),"HS208") -> HS208 | E31: =IFERROR(__xludf.DUMMYFUNCTION("""COMPUTED_VALUE"""),1000.0) -> 1000 | F31: =IFERROR(__xludf.DUMMYFUNCTION("""COMPUTED_VALUE"""),"-") -> - | G31: =IFERROR(__xludf.DUMMYFUNCTION("""COMPUTED_VALUE"""),"Yes") -> Yes
A32: =IFERROR(__xludf.DUMMYFUNCTION("""COMPUTED_VALUE"""),9908.0) -> 9908 | B32: =IFERROR(__xludf.DUMMYFUNCTION("""COMPUTED_VALUE"""),"Alex Kang") -> Alex Kang | C32: =IFERROR(__xludf.DUMMYFUNCTION("""COMPUTED_VALUE"""),11.0) -> 11 | D32: =IFERROR(__xludf.DUMMYFUNCTION("""COMPUTED_VALUE"""),"HS209") -> HS209 | E32: =IFERROR(__xludf.DUMMYFUNCTION("""COMPUTED_VALUE"""),1000.0) -> 1000 | F32: =IFERROR(__xludf.DUMMYFUNCTION("""COMPUTED_VALUE"""),"-") -> - | G32: =IFERROR(__xludf.DUMMYFUNCTION("""COMPUTED_VALUE"""),"Yes") -> Yes
A33: =IFERROR(__xludf.DUMMYFUNCTION("""COMPUTED_VALUE"""),8601.0) -> 8601 | B33: =IFERROR(__xludf.DUMMYFUNCTION("""COMPUTED_VALUE"""),"Mathew Kim") -> Mathew Kim | C33: =IFERROR(__xludf.DUMMYFUNCTION("""COMPUTED_VALUE"""),11.0) -> 11 | D33: =IFERROR(__xludf.DUMMYFUNCTION("""COMPUTED_VALUE"""),"HS210") -> HS210 | E33: =IFERROR(__xludf.DUMMYFUNCTION("""COMPUTED_VALUE"""),1000.0) -> 1000 | F33: =IFERROR(__xludf.DUMMYFUNCTION("""COMPUTED_VALUE"""),"-") -> - | G33: =IFERROR(__xludf.DUMMYFUNCTION("""COMPUTED_VALUE"""),"Yes") -> Yes
A34: =IFERROR(__xludf.DUMMYFUNCTION("""COMPUTED_VALUE"""),3466.0) -> 3466 | B34: =IFERROR(__xludf.DUMMYFUNCTION("""COMPUTED_VALUE"""),"Jay Kim") -> Jay Kim | C34: =IFERROR(__xludf.DUMMYFUNCTION("""COMPUTED_VALUE"""),11.0) -> 11 | D34: =IFERROR(__xludf.DUMMYFUNCTION("""COMPUTED_VALUE"""),"HS211") -> HS211 | E34: =IFERROR(__xludf.DUMMYFUNCTION("""COMPUTED_VALUE"""),130.35) -> 130.35 | F34: =IFERROR(__xludf.DUMMYFUNCTION("""COMPUTED_VALUE"""),"-") -> - | G34: =IFERROR(__xludf.DUMMYFUNCTION("""COMPUTED_VALUE"""),"Yes") -> Yes | H34: =IFERROR(__xludf.DUMMYFUNCTION("""COMPUTED_VALUE"""),46183.64832175926) -> 46183.648
A35: =IFERROR(__xludf.DUMMYFUNCTION("""COMPUTED_VALUE"""),8300.0) -> 8300 | B35: =IFERROR(__xludf.DUMMYFUNCTION("""COMPUTED_VALUE"""),"Andy Lee") -> Andy Lee | C35: =IFERROR(__xludf.DUMMYFUNCTION("""COMPUTED_VALUE"""),11.0) -> 11 | D35: =IFERROR(__xludf.DUMMYFUNCTION("""COMPUTED_VALUE"""),"HS212") -> HS212 | E35: =IFERROR(__xludf.DUMMYFUNCTION("""COMPUTED_VALUE"""),27.22) -> 27.22 | F35: =IFERROR(__xludf.DUMMYFUNCTION("""COMPUTED_VALUE"""),"-") -> - | G35: =IFERROR(__xludf.DUMMYFUNCTION("""COMPUTED_VALUE"""),"Yes") -> Yes | H35: =IFERROR(__xludf.DUMMYFUNCTION("""COMPUTED_VALUE"""),46183.572858796295) -> 46183.573
A36: =IFERROR(__xludf.DUMMYFUNCTION("""COMPUTED_VALUE"""),1688.0) -> 1688 | B36: =IFERROR(__xludf.DUMMYFUNCTION("""COMPUTED_VALUE"""),"Junwoo Yoon") -> Junwoo Yoon | C36: =IFERROR(__xludf.DUMMYFUNCTION("""COMPUTED_VALUE"""),11.0) -> 11 | D36: =IFERROR(__xludf.DUMMYFUNCTION("""COMPUTED_VALUE"""),"HS213") -> HS213 | E36: =IFERROR(__xludf.DUMMYFUNCTION("""COMPUTED_VALUE"""),168.92) -> 168.92 | F36: =IFERROR(__xludf.DUMMYFUNCTION("""COMPUTED_VALUE"""),"-") -> - | G36: =IFERROR(__xludf.DUMMYFUNCTION("""COMPUTED_VALUE"""),"Yes") -> Yes | H36: =IFERROR(__xludf.DUMMYFUNCTION("""COMPUTED_VALUE"""),46183.68376157407) -> 46183.684
A37: =IFERROR(__xludf.DUMMYFUNCTION("""COMPUTED_VALUE"""),8045.0) -> 8045 | B37: =IFERROR(__xludf.DUMMYFUNCTION("""COMPUTED_VALUE"""),"Hyunmo Gu ") -> Hyunmo Gu | C37: =IFERROR(__xludf.DUMMYFUNCTION("""COMPUTED_VALUE"""),11.0) -> 11 | D37: =IFERROR(__xludf.DUMMYFUNCTION("""COMPUTED_VALUE"""),"HS214") -> HS214 | E37: =IFERROR(__xludf.DUMMYFUNCTION("""COMPUTED_VALUE"""),1000.0) -> 1000 | F37: =IFERROR(__xludf.DUMMYFUNCTION("""COMPUTED_VALUE"""),"-") -> - | G37: =IFERROR(__xludf.DUMMYFUNCTION("""COMPUTED_VALUE"""),"Yes") -> Yes
A38: =IFERROR(__xludf.DUMMYFUNCTION("""COMPUTED_VALUE"""),1926.0) -> 1926 | B38: =IFERROR(__xludf.DUMMYFUNCTION("""COMPUTED_VALUE"""),"Sooin Kang") -> Sooin Kang | C38: =IFERROR(__xludf.DUMMYFUNCTION("""COMPUTED_VALUE"""),11.0) -> 11 | D38: =IFERROR(__xludf.DUMMYFUNCTION("""COMPUTED_VALUE"""),"HS215") -> HS215 | E38: =IFERROR(__xludf.DUMMYFUNCTION("""COMPUTED_VALUE"""),1000.0) -> 1000 | F38: =IFERROR(__xludf.DUMMYFUNCTION("""COMPUTED_VALUE"""),"-") -> - | G38: =IFERROR(__xludf.DUMMYFUNCTION("""COMPUTED_VALUE"""),"Yes") -> Yes
A39: =IFERROR(__xludf.DUMMYFUNCTION("""COMPUTED_VALUE"""),1035.0) -> 1035 | B39: =IFERROR(__xludf.DUMMYFUNCTION("""COMPUTED_VALUE"""),"Jiwon Kang") -> Jiwon Kang | C39: =IFERROR(__xludf.DUMMYFUNCTION("""COMPUTED_VALUE"""),11.0) -> 11 | D39: =IFERROR(__xludf.DUMMYFUNCTION("""COMPUTED_VALUE"""),"HS216") -> HS216 | E39: =IFERROR(__xludf.DUMMYFUNCTION("""COMPUTED_VALUE"""),1000.0) -> 1000 | F39: =IFERROR(__xludf.DUMMYFUNCTION("""COMPUTED_VALUE"""),"-") -> - | G39: =IFERROR(__xludf.DUMMYFUNCTION("""COMPUTED_VALUE"""),"Yes") -> Yes
A40: =IFERROR(__xludf.DUMMYFUNCTION("""COMPUTED_VALUE"""),3706.0) -> 3706 | B40: =IFERROR(__xludf.DUMMYFUNCTION("""COMPUTED_VALUE"""),"Kevin Jeon") -> Kevin Jeon | C40: =IFERROR(__xludf.DUMMYFUNCTION("""COMPUTED_VALUE"""),11.0) -> 11 | D40: =IFERROR(__xludf.DUMMYFUNCTION("""COMPUTED_VALUE"""),"HS217") -> HS217 | E40: =IFERROR(__xludf.DUMMYFUNCTION("""COMPUTED_VALUE"""),107.95) -> 107.95 | F40: =IFERROR(__xludf.DUMMYFUNCTION("""COMPUTED_VALUE"""),"-") -> - | G40: =IFERROR(__xludf.DUMMYFUNCTION("""COMPUTED_VALUE"""),"Yes") -> Yes | H40: =IFERROR(__xludf.DUMMYFUNCTION("""COMPUTED_VALUE"""),46183.59241898148) -> 46183.592
A41: =IFERROR(__xludf.DUMMYFUNCTION("""COMPUTED_VALUE"""),1117.0) -> 1117 | B41: =IFERROR(__xludf.DUMMYFUNCTION("""COMPUTED_VALUE"""),"Hyeonjun Kim") -> Hyeonjun Kim | C41: =IFERROR(__xludf.DUMMYFUNCTION("""COMPUTED_VALUE"""),8.0) -> 8 | E41: =IFERROR(__xludf.DUMMYFUNCTION("""COMPUTED_VALUE"""),48.17) -> 48.17 | F41: =IFERROR(__xludf.DUMMYFUNCTION("""COMPUTED_VALUE"""),"-") -> - | G41: =IFERROR(__xludf.DUMMYFUNCTION("""COMPUTED_VALUE"""),"Yes") -> Yes | H41: =IFERROR(__xludf.DUMMYFUNCTION("""COMPUTED_VALUE"""),46185.65935185185) -> 46185.659
...

Sheet Imported_Transactions
A1: =IFERROR(__xludf.DUMMYFUNCTION("IMPORTRANGE(""https://docs.google.com/spreadsheets/d/1xmGsP2eOXdfhJ9DjzCOVFJKoZ2DuuwRb_dbNg1M77M8/edit?gid=138364344#gid=138364344"",""Transactions!A:L"")"),"Money / Store Transaction Log") -> Money / Store Transaction Log
A3: =IFERROR(__xludf.DUMMYFUNCTION("""COMPUTED_VALUE"""),"Timestamp") -> Timestamp | B3: =IFERROR(__xludf.DUMMYFUNCTION("""COMPUTED_VALUE"""),"Date") -> Date | C3: =IFERROR(__xludf.DUMMYFUNCTION("""COMPUTED_VALUE"""),"Card_ID") -> Card_ID | D3: =IFERROR(__xludf.DUMMYFUNCTION("""COMPUTED_VALUE"""),"Student_Name") -> Student_Name | E3: =IFERROR(__xludf.DUMMYFUNCTION("""COMPUTED_VALUE"""),"Mode") -> Mode | F3: =IFERROR(__xludf.DUMMYFUNCTION("""COMPUTED_VALUE"""),"Amount") -> Amount | G3: =IFERROR(__xludf.DUMMYFUNCTION("""COMPUTED_VALUE"""),"Starting_Balance") -> Starting_Balance | H3: =IFERROR(__xludf.DUMMYFUNCTION("""COMPUTED_VALUE"""),"Ending_Balance") -> Ending_Balance | I3: =IFERROR(__xludf.DUMMYFUNCTION("""COMPUTED_VALUE"""),"Item_ID") -> Item_ID | J3: =IFERROR(__xludf.DUMMYFUNCTION("""COMPUTED_VALUE"""),"Item_Name") -> Item_Name | K3: =IFERROR(__xludf.DUMMYFUNCTION("""COMPUTED_VALUE"""),"Note") -> Note | L3: =IFERROR(__xludf.DUMMYFUNCTION("""COMPUTED_VALUE"""),"Status") -> Status
A4: =IFERROR(__xludf.DUMMYFUNCTION("""COMPUTED_VALUE"""),46163.34710648148) -> 46163.347 | B4: =IFERROR(__xludf.DUMMYFUNCTION("""COMPUTED_VALUE"""),46163.0) -> 46163 | C4: =IFERROR(__xludf.DUMMYFUNCTION("""COMPUTED_VALUE"""),"5c07fef4") -> 5c07fef4 | D4: =IFERROR(__xludf.DUMMYFUNCTION("""COMPUTED_VALUE"""),"Tiffany Kim") -> Tiffany Kim | E4: =IFERROR(__xludf.DUMMYFUNCTION("""COMPUTED_VALUE"""),"REWARD") -> REWARD | F4: =IFERROR(__xludf.DUMMYFUNCTION("""COMPUTED_VALUE"""),10.0) -> 10 | G4: =IFERROR(__xludf.DUMMYFUNCTION("""COMPUTED_VALUE"""),0.0) -> 0 | H4: =IFERROR(__xludf.DUMMYFUNCTION("""COMPUTED_VALUE"""),10.0) -> 10 | K4: =IFERROR(__xludf.DUMMYFUNCTION("""COMPUTED_VALUE"""),"On-time attendance reward") -> On-time attendance reward | L4: =IFERROR(__xludf.DUMMYFUNCTION("""COMPUTED_VALUE"""),"Success") -> Success
A5: =IFERROR(__xludf.DUMMYFUNCTION("""COMPUTED_VALUE"""),46163.34847222222) -> 46163.348 | B5: =IFERROR(__xludf.DUMMYFUNCTION("""COMPUTED_VALUE"""),46163.0) -> 46163 | C5: =IFERROR(__xludf.DUMMYFUNCTION("""COMPUTED_VALUE"""),"babde4c4") -> babde4c4 | D5: =IFERROR(__xludf.DUMMYFUNCTION("""COMPUTED_VALUE"""),"Ashley Guk") -> Ashley Guk | E5: =IFERROR(__xludf.DUMMYFUNCTION("""COMPUTED_VALUE"""),"REWARD") -> REWARD | F5: =IFERROR(__xludf.DUMMYFUNCTION("""COMPUTED_VALUE"""),10.0) -> 10 | G5: =IFERROR(__xludf.DUMMYFUNCTION("""COMPUTED_VALUE"""),0.0) -> 0 | H5: =IFERROR(__xludf.DUMMYFUNCTION("""COMPUTED_VALUE"""),10.0) -> 10 | K5: =IFERROR(__xludf.DUMMYFUNCTION("""COMPUTED_VALUE"""),"On-time attendance reward") -> On-time attendance reward | L5: =IFERROR(__xludf.DUMMYFUNCTION("""COMPUTED_VALUE"""),"Success") -> Success
A6: =IFERROR(__xludf.DUMMYFUNCTION("""COMPUTED_VALUE"""),46164.34847222222) -> 46164.348 | B6: =IFERROR(__xludf.DUMMYFUNCTION("""COMPUTED_VALUE"""),46164.0) -> 46164 | C6: =IFERROR(__xludf.DUMMYFUNCTION("""COMPUTED_VALUE"""),"ba912211") -> ba912211 | D6: =IFERROR(__xludf.DUMMYFUNCTION("""COMPUTED_VALUE"""),"Daisy Dou") -> Daisy Dou | E6: =IFERROR(__xludf.DUMMYFUNCTION("""COMPUTED_VALUE"""),"REWARD") -> REWARD | F6: =IFERROR(__xludf.DUMMYFUNCTION("""COMPUTED_VALUE"""),10.0) -> 10 | G6: =IFERROR(__xludf.DUMMYFUNCTION("""COMPUTED_VALUE"""),0.0) -> 0 | H6: =IFERROR(__xludf.DUMMYFUNCTION("""COMPUTED_VALUE"""),10.0) -> 10 | K6: =IFERROR(__xludf.DUMMYFUNCTION("""COMPUTED_VALUE"""),"On-time attendance reward") -> On-time attendance reward | L6: =IFERROR(__xludf.DUMMYFUNCTION("""COMPUTED_VALUE"""),"Success") -> Success
A7: =IFERROR(__xludf.DUMMYFUNCTION("""COMPUTED_VALUE"""),46163.34946759259) -> 46163.349 | B7: =IFERROR(__xludf.DUMMYFUNCTION("""COMPUTED_VALUE"""),46163.0) -> 46163 | C7: =IFERROR(__xludf.DUMMYFUNCTION("""COMPUTED_VALUE"""),"dc04eef4") -> dc04eef4 | D7: =IFERROR(__xludf.DUMMYFUNCTION("""COMPUTED_VALUE"""),"Joshua Jung") -> Joshua Jung | E7: =IFERROR(__xludf.DUMMYFUNCTION("""COMPUTED_VALUE"""),"REWARD") -> REWARD | F7: =IFERROR(__xludf.DUMMYFUNCTION("""COMPUTED_VALUE"""),10.0) -> 10 | G7: =IFERROR(__xludf.DUMMYFUNCTION("""COMPUTED_VALUE"""),0.0) -> 0 | H7: =IFERROR(__xludf.DUMMYFUNCTION("""COMPUTED_VALUE"""),10.0) -> 10 | K7: =IFERROR(__xludf.DUMMYFUNCTION("""COMPUTED_VALUE"""),"On-time attendance reward") -> On-time attendance reward | L7: =IFERROR(__xludf.DUMMYFUNCTION("""COMPUTED_VALUE"""),"Success") -> Success
A8: =IFERROR(__xludf.DUMMYFUNCTION("""COMPUTED_VALUE"""),46163.35591435185) -> 46163.356 | B8: =IFERROR(__xludf.DUMMYFUNCTION("""COMPUTED_VALUE"""),46163.0) -> 46163 | C8: =IFERROR(__xludf.DUMMYFUNCTION("""COMPUTED_VALUE"""),"5a032611") -> 5a032611 | D8: =IFERROR(__xludf.DUMMYFUNCTION("""COMPUTED_VALUE"""),"Harold Dou") -> Harold Dou | E8: =IFERROR(__xludf.DUMMYFUNCTION("""COMPUTED_VALUE"""),"REWARD") -> REWARD | F8: =IFERROR(__xludf.DUMMYFUNCTION("""COMPUTED_VALUE"""),10.0) -> 10 | G8: =IFERROR(__xludf.DUMMYFUNCTION("""COMPUTED_VALUE"""),0.0) -> 0 | H8: =IFERROR(__xludf.DUMMYFUNCTION("""COMPUTED_VALUE"""),10.0) -> 10 | K8: =IFERROR(__xludf.DUMMYFUNCTION("""COMPUTED_VALUE"""),"On-time attendance reward") -> On-time attendance reward | L8: =IFERROR(__xludf.DUMMYFUNCTION("""COMPUTED_VALUE"""),"Success") -> Success
A9: =IFERROR(__xludf.DUMMYFUNCTION("""COMPUTED_VALUE"""),46163.356261574074) -> 46163.356 | B9: =IFERROR(__xludf.DUMMYFUNCTION("""COMPUTED_VALUE"""),46163.0) -> 46163 | C9: =IFERROR(__xludf.DUMMYFUNCTION("""COMPUTED_VALUE"""),"ba353911") -> ba353911 | D9: =IFERROR(__xludf.DUMMYFUNCTION("""COMPUTED_VALUE"""),"Dayeon Kang") -> Dayeon Kang | E9: =IFERROR(__xludf.DUMMYFUNCTION("""COMPUTED_VALUE"""),"REWARD") -> REWARD | F9: =IFERROR(__xludf.DUMMYFUNCTION("""COMPUTED_VALUE"""),10.0) -> 10 | G9: =IFERROR(__xludf.DUMMYFUNCTION("""COMPUTED_VALUE"""),0.0) -> 0 | H9: =IFERROR(__xludf.DUMMYFUNCTION("""COMPUTED_VALUE"""),10.0) -> 10 | K9: =IFERROR(__xludf.DUMMYFUNCTION("""COMPUTED_VALUE"""),"On-time attendance reward") -> On-time attendance reward | L9: =IFERROR(__xludf.DUMMYFUNCTION("""COMPUTED_VALUE"""),"Success") -> Success
A10: =IFERROR(__xludf.DUMMYFUNCTION("""COMPUTED_VALUE"""),46164.356261574074) -> 46164.356 | B10: =IFERROR(__xludf.DUMMYFUNCTION("""COMPUTED_VALUE"""),46164.0) -> 46164 | C10: =IFERROR(__xludf.DUMMYFUNCTION("""COMPUTED_VALUE"""),"7c4e261e") -> 7c4e261e | D10: =IFERROR(__xludf.DUMMYFUNCTION("""COMPUTED_VALUE"""),"Suha Lee") -> Suha Lee | E10: =IFERROR(__xludf.DUMMYFUNCTION("""COMPUTED_VALUE"""),"REWARD") -> REWARD | F10: =IFERROR(__xludf.DUMMYFUNCTION("""COMPUTED_VALUE"""),10.0) -> 10 | G10: =IFERROR(__xludf.DUMMYFUNCTION("""COMPUTED_VALUE"""),0.0) -> 0 | H10: =IFERROR(__xludf.DUMMYFUNCTION("""COMPUTED_VALUE"""),10.0) -> 10 | K10: =IFERROR(__xludf.DUMMYFUNCTION("""COMPUTED_VALUE"""),"On-time attendance reward") -> On-time attendance reward | L10: =IFERROR(__xludf.DUMMYFUNCTION("""COMPUTED_VALUE"""),"Success") -> Success
A11: =IFERROR(__xludf.DUMMYFUNCTION("""COMPUTED_VALUE"""),46163.36684027778) -> 46163.367 | B11: =IFERROR(__xludf.DUMMYFUNCTION("""COMPUTED_VALUE"""),46163.0) -> 46163 | C11: =IFERROR(__xludf.DUMMYFUNCTION("""COMPUTED_VALUE"""),"9a5f2811") -> 9a5f2811 | D11: =IFERROR(__xludf.DUMMYFUNCTION("""COMPUTED_VALUE"""),"Junyoung Yoo") -> Junyoung Yoo | E11: =IFERROR(__xludf.DUMMYFUNCTION("""COMPUTED_VALUE"""),"FINE") -> FINE | F11: =IFERROR(__xludf.DUMMYFUNCTION("""COMPUTED_VALUE"""),10.0) -> 10 | G11: =IFERROR(__xludf.DUMMYFUNCTION("""COMPUTED_VALUE"""),0.0) -> 0 | H11: =IFERROR(__xludf.DUMMYFUNCTION("""COMPUTED_VALUE"""),0.0) -> 0 | K11: =IFERROR(__xludf.DUMMYFUNCTION("""COMPUTED_VALUE"""),"Late attendance penalty") -> Late attendance penalty | L11: =IFERROR(__xludf.DUMMYFUNCTION("""COMPUTED_VALUE"""),"Denied - insufficient balance") -> Denied - insufficient balance
A12: =IFERROR(__xludf.DUMMYFUNCTION("""COMPUTED_VALUE"""),46164.36684027778) -> 46164.367 | B12: =IFERROR(__xludf.DUMMYFUNCTION("""COMPUTED_VALUE"""),46164.0) -> 46164 | C12: =IFERROR(__xludf.DUMMYFUNCTION("""COMPUTED_VALUE"""),"1e3e1410") -> 1e3e1410 | D12: =IFERROR(__xludf.DUMMYFUNCTION("""COMPUTED_VALUE"""),"Junjae Park") -> Junjae Park | E12: =IFERROR(__xludf.DUMMYFUNCTION("""COMPUTED_VALUE"""),"FINE") -> FINE | F12: =IFERROR(__xludf.DUMMYFUNCTION("""COMPUTED_VALUE"""),10.0) -> 10 | G12: =IFERROR(__xludf.DUMMYFUNCTION("""COMPUTED_VALUE"""),0.0) -> 0 | H12: =IFERROR(__xludf.DUMMYFUNCTION("""COMPUTED_VALUE"""),0.0) -> 0 | K12: =IFERROR(__xludf.DUMMYFUNCTION("""COMPUTED_VALUE"""),"Late attendance penalty") -> Late attendance penalty | L12: =IFERROR(__xludf.DUMMYFUNCTION("""COMPUTED_VALUE"""),"Denied - insufficient balance") -> Denied - insufficient balance
A13: =IFERROR(__xludf.DUMMYFUNCTION("""COMPUTED_VALUE"""),46163.465162037035) -> 46163.465 | B13: =IFERROR(__xludf.DUMMYFUNCTION("""COMPUTED_VALUE"""),46163.0) -> 46163 | C13: =IFERROR(__xludf.DUMMYFUNCTION("""COMPUTED_VALUE"""),"9a5f2811") -> 9a5f2811 | D13: =IFERROR(__xludf.DUMMYFUNCTION("""COMPUTED_VALUE"""),"Junyoung Yoo") -> Junyoung Yoo | E13: =IFERROR(__xludf.DUMMYFUNCTION("""COMPUTED_VALUE"""),"DEPOSIT") -> DEPOSIT | F13: =IFERROR(__xludf.DUMMYFUNCTION("""COMPUTED_VALUE"""),20.0) -> 20 | G13: =IFERROR(__xludf.DUMMYFUNCTION("""COMPUTED_VALUE"""),0.0) -> 0 | H13: =IFERROR(__xludf.DUMMYFUNCTION("""COMPUTED_VALUE"""),20.0) -> 20 | L13: =IFERROR(__xludf.DUMMYFUNCTION("""COMPUTED_VALUE"""),"Success") -> Success
A14: =IFERROR(__xludf.DUMMYFUNCTION("""COMPUTED_VALUE"""),46163.46760416667) -> 46163.468 | B14: =IFERROR(__xludf.DUMMYFUNCTION("""COMPUTED_VALUE"""),46163.0) -> 46163 | C14: =IFERROR(__xludf.DUMMYFUNCTION("""COMPUTED_VALUE"""),"7c4e261e") -> 7c4e261e | D14: =IFERROR(__xludf.DUMMYFUNCTION("""COMPUTED_VALUE"""),"Suha Lee") -> Suha Lee | E14: =IFERROR(__xludf.DUMMYFUNCTION("""COMPUTED_VALUE"""),"DEPOSIT") -> DEPOSIT | F14: =IFERROR(__xludf.DUMMYFUNCTION("""COMPUTED_VALUE"""),20.0) -> 20 | G14: =IFERROR(__xludf.DUMMYFUNCTION("""COMPUTED_VALUE"""),10.0) -> 10 | H14: =IFERROR(__xludf.DUMMYFUNCTION("""COMPUTED_VALUE"""),30.0) -> 30 | L14: =IFERROR(__xludf.DUMMYFUNCTION("""COMPUTED_VALUE"""),"Success") -> Success
A15: =IFERROR(__xludf.DUMMYFUNCTION("""COMPUTED_VALUE"""),46163.469618055555) -> 46163.47 | B15: =IFERROR(__xludf.DUMMYFUNCTION("""COMPUTED_VALUE"""),46163.0) -> 46163 | C15: =IFERROR(__xludf.DUMMYFUNCTION("""COMPUTED_VALUE"""),"5a032611") -> 5a032611 | D15: =IFERROR(__xludf.DUMMYFUNCTION("""COMPUTED_VALUE"""),"Harold Dou") -> Harold Dou | E15: =IFERROR(__xludf.DUMMYFUNCTION("""COMPUTED_VALUE"""),"DEPOSIT") -> DEPOSIT | F15: =IFERROR(__xludf.DUMMYFUNCTION("""COMPUTED_VALUE"""),20.0) -> 20 | G15: =IFERROR(__xludf.DUMMYFUNCTION("""COMPUTED_VALUE"""),10.0) -> 10 | H15: =IFERROR(__xludf.DUMMYFUNCTION("""COMPUTED_VALUE"""),30.0) -> 30 | L15: =IFERROR(__xludf.DUMMYFUNCTION("""COMPUTED_VALUE"""),"Success") -> Success
A16: =IFERROR(__xludf.DUMMYFUNCTION("""COMPUTED_VALUE"""),46163.472037037034) -> 46163.472 | B16: =IFERROR(__xludf.DUMMYFUNCTION("""COMPUTED_VALUE"""),46163.0) -> 46163 | C16: =IFERROR(__xludf.DUMMYFUNCTION("""COMPUTED_VALUE"""),"babde4c4") -> babde4c4 | D16: =IFERROR(__xludf.DUMMYFUNCTION("""COMPUTED_VALUE"""),"Ashley Guk") -> Ashley Guk | E16: =IFERROR(__xludf.DUMMYFUNCTION("""COMPUTED_VALUE"""),"DEPOSIT") -> DEPOSIT | F16: =IFERROR(__xludf.DUMMYFUNCTION("""COMPUTED_VALUE"""),20.0) -> 20 | G16: =IFERROR(__xludf.DUMMYFUNCTION("""COMPUTED_VALUE"""),10.0) -> 10 | H16: =IFERROR(__xludf.DUMMYFUNCTION("""COMPUTED_VALUE"""),30.0) -> 30 | L16: =IFERROR(__xludf.DUMMYFUNCTION("""COMPUTED_VALUE"""),"Success") -> Success
A17: =IFERROR(__xludf.DUMMYFUNCTION("""COMPUTED_VALUE"""),46163.474490740744) -> 46163.474 | B17: =IFERROR(__xludf.DUMMYFUNCTION("""COMPUTED_VALUE"""),46163.0) -> 46163 | C17: =IFERROR(__xludf.DUMMYFUNCTION("""COMPUTED_VALUE"""),"dc04eef4") -> dc04eef4 | D17: =IFERROR(__xludf.DUMMYFUNCTION("""COMPUTED_VALUE"""),"Joshua Jung") -> Joshua Jung | E17: =IFERROR(__xludf.DUMMYFUNCTION("""COMPUTED_VALUE"""),"DEPOSIT") -> DEPOSIT | F17: =IFERROR(__xludf.DUMMYFUNCTION("""COMPUTED_VALUE"""),20.0) -> 20 | G17: =IFERROR(__xludf.DUMMYFUNCTION("""COMPUTED_VALUE"""),10.0) -> 10 | H17: =IFERROR(__xludf.DUMMYFUNCTION("""COMPUTED_VALUE"""),30.0) -> 30 | L17: =IFERROR(__xludf.DUMMYFUNCTION("""COMPUTED_VALUE"""),"Success") -> Success
A18: =IFERROR(__xludf.DUMMYFUNCTION("""COMPUTED_VALUE"""),46163.47461805555) -> 46163.475 | B18: =IFERROR(__xludf.DUMMYFUNCTION("""COMPUTED_VALUE"""),46163.0) -> 46163 | C18: =IFERROR(__xludf.DUMMYFUNCTION("""COMPUTED_VALUE"""),"1e3e1410") -> 1e3e1410 | D18: =IFERROR(__xludf.DUMMYFUNCTION("""COMPUTED_VALUE"""),"Junjae Park") -> Junjae Park | E18: =IFERROR(__xludf.DUMMYFUNCTION("""COMPUTED_VALUE"""),"DEPOSIT") -> DEPOSIT | F18: =IFERROR(__xludf.DUMMYFUNCTION("""COMPUTED_VALUE"""),20.0) -> 20 | G18: =IFERROR(__xludf.DUMMYFUNCTION("""COMPUTED_VALUE"""),0.0) -> 0 | H18: =IFERROR(__xludf.DUMMYFUNCTION("""COMPUTED_VALUE"""),20.0) -> 20 | L18: =IFERROR(__xludf.DUMMYFUNCTION("""COMPUTED_VALUE"""),"Success") -> Success
A19: =IFERROR(__xludf.DUMMYFUNCTION("""COMPUTED_VALUE"""),46164.34457175926) -> 46164.345 | B19: =IFERROR(__xludf.DUMMYFUNCTION("""COMPUTED_VALUE"""),46164.0) -> 46164 | C19: =IFERROR(__xludf.DUMMYFUNCTION("""COMPUTED_VALUE"""),"5c07fef4") -> 5c07fef4 | D19: =IFERROR(__xludf.DUMMYFUNCTION("""COMPUTED_VALUE"""),"Tiffany Kim") -> Tiffany Kim | E19: =IFERROR(__xludf.DUMMYFUNCTION("""COMPUTED_VALUE"""),"REWARD") -> REWARD | F19: =IFERROR(__xludf.DUMMYFUNCTION("""COMPUTED_VALUE"""),10.0) -> 10 | G19: =IFERROR(__xludf.DUMMYFUNCTION("""COMPUTED_VALUE"""),10.0) -> 10 | H19: =IFERROR(__xludf.DUMMYFUNCTION("""COMPUTED_VALUE"""),20.0) -> 20 | K19: =IFERROR(__xludf.DUMMYFUNCTION("""COMPUTED_VALUE"""),"On-time attendance reward") -> On-time attendance reward | L19: =IFERROR(__xludf.DUMMYFUNCTION("""COMPUTED_VALUE"""),"Success") -> Success
A20: =IFERROR(__xludf.DUMMYFUNCTION("""COMPUTED_VALUE"""),46164.353368055556) -> 46164.353 | B20: =IFERROR(__xludf.DUMMYFUNCTION("""COMPUTED_VALUE"""),46164.0) -> 46164 | C20: =IFERROR(__xludf.DUMMYFUNCTION("""COMPUTED_VALUE"""),"dc04eef4") -> dc04eef4 | D20: =IFERROR(__xludf.DUMMYFUNCTION("""COMPUTED_VALUE"""),"Joshua Jung") -> Joshua Jung | E20: =IFERROR(__xludf.DUMMYFUNCTION("""COMPUTED_VALUE"""),"REWARD") -> REWARD | F20: =IFERROR(__xludf.DUMMYFUNCTION("""COMPUTED_VALUE"""),10.0) -> 10 | G20: =IFERROR(__xludf.DUMMYFUNCTION("""COMPUTED_VALUE"""),30.0) -> 30 | H20: =IFERROR(__xludf.DUMMYFUNCTION("""COMPUTED_VALUE"""),40.0) -> 40 | K20: =IFERROR(__xludf.DUMMYFUNCTION("""COMPUTED_VALUE"""),"On-time attendance reward") -> On-time attendance reward | L20: =IFERROR(__xludf.DUMMYFUNCTION("""COMPUTED_VALUE"""),"Success") -> Success
A21: =IFERROR(__xludf.DUMMYFUNCTION("""COMPUTED_VALUE"""),46164.35349537037) -> 46164.353 | B21: =IFERROR(__xludf.DUMMYFUNCTION("""COMPUTED_VALUE"""),46164.0) -> 46164 | C21: =IFERROR(__xludf.DUMMYFUNCTION("""COMPUTED_VALUE"""),"ba912211") -> ba912211 | D21: =IFERROR(__xludf.DUMMYFUNCTION("""COMPUTED_VALUE"""),"Daisy Dou") -> Daisy Dou | E21: =IFERROR(__xludf.DUMMYFUNCTION("""COMPUTED_VALUE"""),"REWARD") -> REWARD | F21: =IFERROR(__xludf.DUMMYFUNCTION("""COMPUTED_VALUE"""),10.0) -> 10 | G21: =IFERROR(__xludf.DUMMYFUNCTION("""COMPUTED_VALUE"""),10.0) -> 10 | H21: =IFERROR(__xludf.DUMMYFUNCTION("""COMPUTED_VALUE"""),20.0) -> 20 | K21: =IFERROR(__xludf.DUMMYFUNCTION("""COMPUTED_VALUE"""),"On-time attendance reward") -> On-time attendance reward | L21: =IFERROR(__xludf.DUMMYFUNCTION("""COMPUTED_VALUE"""),"Success") -> Success
A22: =IFERROR(__xludf.DUMMYFUNCTION("""COMPUTED_VALUE"""),46164.353634259256) -> 46164.354 | B22: =IFERROR(__xludf.DUMMYFUNCTION("""COMPUTED_VALUE"""),46164.0) -> 46164 | C22: =IFERROR(__xludf.DUMMYFUNCTION("""COMPUTED_VALUE"""),"babde4c4") -> babde4c4 | D22: =IFERROR(__xludf.DUMMYFUNCTION("""COMPUTED_VALUE"""),"Ashley Guk") -> Ashley Guk | E22: =IFERROR(__xludf.DUMMYFUNCTION("""COMPUTED_VALUE"""),"REWARD") -> REWARD | F22: =IFERROR(__xludf.DUMMYFUNCTION("""COMPUTED_VALUE"""),10.0) -> 10 | G22: =IFERROR(__xludf.DUMMYFUNCTION("""COMPUTED_VALUE"""),30.0) -> 30 | H22: =IFERROR(__xludf.DUMMYFUNCTION("""COMPUTED_VALUE"""),40.0) -> 40 | K22: =IFERROR(__xludf.DUMMYFUNCTION("""COMPUTED_VALUE"""),"On-time attendance reward") -> On-time attendance reward | L22: =IFERROR(__xludf.DUMMYFUNCTION("""COMPUTED_VALUE"""),"Success") -> Success
A23: =IFERROR(__xludf.DUMMYFUNCTION("""COMPUTED_VALUE"""),46164.354409722226) -> 46164.354 | B23: =IFERROR(__xludf.DUMMYFUNCTION("""COMPUTED_VALUE"""),46164.0) -> 46164 | C23: =IFERROR(__xludf.DUMMYFUNCTION("""COMPUTED_VALUE"""),"7c4e261e") -> 7c4e261e | D23: =IFERROR(__xludf.DUMMYFUNCTION("""COMPUTED_VALUE"""),"Suha Lee") -> Suha Lee | E23: =IFERROR(__xludf.DUMMYFUNCTION("""COMPUTED_VALUE"""),"REWARD") -> REWARD | F23: =IFERROR(__xludf.DUMMYFUNCTION("""COMPUTED_VALUE"""),10.0) -> 10 | G23: =IFERROR(__xludf.DUMMYFUNCTION("""COMPUTED_VALUE"""),30.0) -> 30 | H23: =IFERROR(__xludf.DUMMYFUNCTION("""COMPUTED_VALUE"""),40.0) -> 40 | K23: =IFERROR(__xludf.DUMMYFUNCTION("""COMPUTED_VALUE"""),"On-time attendance reward") -> On-time attendance reward | L23: =IFERROR(__xludf.DUMMYFUNCTION("""COMPUTED_VALUE"""),"Success") -> Success
A24: =IFERROR(__xludf.DUMMYFUNCTION("""COMPUTED_VALUE"""),46164.35689814815) -> 46164.357 | B24: =IFERROR(__xludf.DUMMYFUNCTION("""COMPUTED_VALUE"""),46164.0) -> 46164 | C24: =IFERROR(__xludf.DUMMYFUNCTION("""COMPUTED_VALUE"""),"ba353911") -> ba353911 | D24: =IFERROR(__xludf.DUMMYFUNCTION("""COMPUTED_VALUE"""),"Dayeon Kang") -> Dayeon Kang | E24: =IFERROR(__xludf.DUMMYFUNCTION("""COMPUTED_VALUE"""),"REWARD") -> REWARD | F24: =IFERROR(__xludf.DUMMYFUNCTION("""COMPUTED_VALUE"""),10.0) -> 10 | G24: =IFERROR(__xludf.DUMMYFUNCTION("""COMPUTED_VALUE"""),10.0) -> 10 | H24: =IFERROR(__xludf.DUMMYFUNCTION("""COMPUTED_VALUE"""),20.0) -> 20 | K24: =IFERROR(__xludf.DUMMYFUNCTION("""COMPUTED_VALUE"""),"On-time attendance reward") -> On-time attendance reward | L24: =IFERROR(__xludf.DUMMYFUNCTION("""COMPUTED_VALUE"""),"Success") -> Success
A25: =IFERROR(__xludf.DUMMYFUNCTION("""COMPUTED_VALUE"""),46164.357037037036) -> 46164.357 | B25: =IFERROR(__xludf.DUMMYFUNCTION("""COMPUTED_VALUE"""),46164.0) -> 46164 | C25: =IFERROR(__xludf.DUMMYFUNCTION("""COMPUTED_VALUE"""),"5a032611") -> 5a032611 | D25: =IFERROR(__xludf.DUMMYFUNCTION("""COMPUTED_VALUE"""),"Harold Dou") -> Harold Dou | E25: =IFERROR(__xludf.DUMMYFUNCTION("""COMPUTED_VALUE"""),"REWARD") -> REWARD | F25: =IFERROR(__xludf.DUMMYFUNCTION("""COMPUTED_VALUE"""),10.0) -> 10 | G25: =IFERROR(__xludf.DUMMYFUNCTION("""COMPUTED_VALUE"""),30.0) -> 30 | H25: =IFERROR(__xludf.DUMMYFUNCTION("""COMPUTED_VALUE"""),40.0) -> 40 | K25: =IFERROR(__xludf.DUMMYFUNCTION("""COMPUTED_VALUE"""),"On-time attendance reward") -> On-time attendance reward | L25: =IFERROR(__xludf.DUMMYFUNCTION("""COMPUTED_VALUE"""),"Success") -> Success
A26: =IFERROR(__xludf.DUMMYFUNCTION("""COMPUTED_VALUE"""),46164.35717592593) -> 46164.357 | B26: =IFERROR(__xludf.DUMMYFUNCTION("""COMPUTED_VALUE"""),46164.0) -> 46164 | C26: =IFERROR(__xludf.DUMMYFUNCTION("""COMPUTED_VALUE"""),"9a5f2811") -> 9a5f2811 | D26: =IFERROR(__xludf.DUMMYFUNCTION("""COMPUTED_VALUE"""),"Junyoung Yoo") -> Junyoung Yoo | E26: =IFERROR(__xludf.DUMMYFUNCTION("""COMPUTED_VALUE"""),"REWARD") -> REWARD | F26: =IFERROR(__xludf.DUMMYFUNCTION("""COMPUTED_VALUE"""),10.0) -> 10 | G26: =IFERROR(__xludf.DUMMYFUNCTION("""COMPUTED_VALUE"""),20.0) -> 20 | H26: =IFERROR(__xludf.DUMMYFUNCTION("""COMPUTED_VALUE"""),30.0) -> 30 | K26: =IFERROR(__xludf.DUMMYFUNCTION("""COMPUTED_VALUE"""),"On-time attendance reward") -> On-time attendance reward | L26: =IFERROR(__xludf.DUMMYFUNCTION("""COMPUTED_VALUE"""),"Success") -> Success
A27: =IFERROR(__xludf.DUMMYFUNCTION("""COMPUTED_VALUE"""),46164.35865740741) -> 46164.359 | B27: =IFERROR(__xludf.DUMMYFUNCTION("""COMPUTED_VALUE"""),46164.0) -> 46164 | C27: =IFERROR(__xludf.DUMMYFUNCTION("""COMPUTED_VALUE"""),"ba912211") -> ba912211 | D27: =IFERROR(__xludf.DUMMYFUNCTION("""COMPUTED_VALUE"""),"Daisy Dou") -> Daisy Dou | E27: =IFERROR(__xludf.DUMMYFUNCTION("""COMPUTED_VALUE"""),"DEPOSIT") -> DEPOSIT | F27: =IFERROR(__xludf.DUMMYFUNCTION("""COMPUTED_VALUE"""),71.0) -> 71 | G27: =IFERROR(__xludf.DUMMYFUNCTION("""COMPUTED_VALUE"""),20.0) -> 20 | H27: =IFERROR(__xludf.DUMMYFUNCTION("""COMPUTED_VALUE"""),91.0) -> 91 | L27: =IFERROR(__xludf.DUMMYFUNCTION("""COMPUTED_VALUE"""),"Success") -> Success
A28: =IFERROR(__xludf.DUMMYFUNCTION("""COMPUTED_VALUE"""),46164.359143518515) -> 46164.359 | B28: =IFERROR(__xludf.DUMMYFUNCTION("""COMPUTED_VALUE"""),46164.0) -> 46164 | C28: =IFERROR(__xludf.DUMMYFUNCTION("""COMPUTED_VALUE"""),"babde4c4") -> babde4c4 | D28: =IFERROR(__xludf.DUMMYFUNCTION("""COMPUTED_VALUE"""),"Ashley Guk") -> Ashley Guk | E28: =IFERROR(__xludf.DUMMYFUNCTION("""COMPUTED_VALUE"""),"DEPOSIT") -> DEPOSIT | F28: =IFERROR(__xludf.DUMMYFUNCTION("""COMPUTED_VALUE"""),16.0) -> 16 | G28: =IFERROR(__xludf.DUMMYFUNCTION("""COMPUTED_VALUE"""),40.0) -> 40 | H28: =IFERROR(__xludf.DUMMYFUNCTION("""COMPUTED_VALUE"""),56.0) -> 56 | L28: =IFERROR(__xludf.DUMMYFUNCTION("""COMPUTED_VALUE"""),"Success") -> Success
A29: =IFERROR(__xludf.DUMMYFUNCTION("""COMPUTED_VALUE"""),46168.33908564815) -> 46168.339 | B29: =IFERROR(__xludf.DUMMYFUNCTION("""COMPUTED_VALUE"""),46168.0) -> 46168 | C29: =IFERROR(__xludf.DUMMYFUNCTION("""COMPUTED_VALUE"""),"dc04eef4") -> dc04eef4 | D29: =IFERROR(__xludf.DUMMYFUNCTION("""COMPUTED_VALUE"""),"Joshua Jung") -> Joshua Jung | E29: =IFERROR(__xludf.DUMMYFUNCTION("""COMPUTED_VALUE"""),"REWARD") -> REWARD | F29: =IFERROR(__xludf.DUMMYFUNCTION("""COMPUTED_VALUE"""),10.0) -> 10 | G29: =IFERROR(__xludf.DUMMYFUNCTION("""COMPUTED_VALUE"""),40.0) -> 40 | H29: =IFERROR(__xludf.DUMMYFUNCTION("""COMPUTED_VALUE"""),50.0) -> 50 | K29: =IFERROR(__xludf.DUMMYFUNCTION("""COMPUTED_VALUE"""),"On-time attendance reward") -> On-time attendance reward | L29: =IFERROR(__xludf.DUMMYFUNCTION("""COMPUTED_VALUE"""),"Success") -> Success
A30: =IFERROR(__xludf.DUMMYFUNCTION("""COMPUTED_VALUE"""),46168.350902777776) -> 46168.351 | B30: =IFERROR(__xludf.DUMMYFUNCTION("""COMPUTED_VALUE"""),46168.0) -> 46168 | C30: =IFERROR(__xludf.DUMMYFUNCTION("""COMPUTED_VALUE"""),"5c07fef4") -> 5c07fef4 | D30: =IFERROR(__xludf.DUMMYFUNCTION("""COMPUTED_VALUE"""),"Tiffany Kim") -> Tiffany Kim | E30: =IFERROR(__xludf.DUMMYFUNCTION("""COMPUTED_VALUE"""),"REWARD") -> REWARD | F30: =IFERROR(__xludf.DUMMYFUNCTION("""COMPUTED_VALUE"""),10.0) -> 10 | G30: =IFERROR(__xludf.DUMMYFUNCTION("""COMPUTED_VALUE"""),20.0) -> 20 | H30: =IFERROR(__xludf.DUMMYFUNCTION("""COMPUTED_VALUE"""),30.0) -> 30 | K30: =IFERROR(__xludf.DUMMYFUNCTION("""COMPUTED_VALUE"""),"On-time attendance reward") -> On-time attendance reward | L30: =IFERROR(__xludf.DUMMYFUNCTION("""COMPUTED_VALUE"""),"Success") -> Success
A31: =IFERROR(__xludf.DUMMYFUNCTION("""COMPUTED_VALUE"""),46168.351643518516) -> 46168.352 | B31: =IFERROR(__xludf.DUMMYFUNCTION("""COMPUTED_VALUE"""),46168.0) -> 46168 | C31: =IFERROR(__xludf.DUMMYFUNCTION("""COMPUTED_VALUE"""),"ba912211") -> ba912211 | D31: =IFERROR(__xludf.DUMMYFUNCTION("""COMPUTED_VALUE"""),"Daisy Dou") -> Daisy Dou | E31: =IFERROR(__xludf.DUMMYFUNCTION("""COMPUTED_VALUE"""),"REWARD") -> REWARD | F31: =IFERROR(__xludf.DUMMYFUNCTION("""COMPUTED_VALUE"""),10.0) -> 10 | G31: =IFERROR(__xludf.DUMMYFUNCTION("""COMPUTED_VALUE"""),91.0) -> 91 | H31: =IFERROR(__xludf.DUMMYFUNCTION("""COMPUTED_VALUE"""),101.0) -> 101 | K31: =IFERROR(__xludf.DUMMYFUNCTION("""COMPUTED_VALUE"""),"On-time attendance reward") -> On-time attendance reward | L31: =IFERROR(__xludf.DUMMYFUNCTION("""COMPUTED_VALUE"""),"Success") -> Success
A32: =IFERROR(__xludf.DUMMYFUNCTION("""COMPUTED_VALUE"""),46168.35450231482) -> 46168.355 | B32: =IFERROR(__xludf.DUMMYFUNCTION("""COMPUTED_VALUE"""),46168.0) -> 46168 | C32: =IFERROR(__xludf.DUMMYFUNCTION("""COMPUTED_VALUE"""),"7c4e261e") -> 7c4e261e | D32: =IFERROR(__xludf.DUMMYFUNCTION("""COMPUTED_VALUE"""),"Suha Lee") -> Suha Lee | E32: =IFERROR(__xludf.DUMMYFUNCTION("""COMPUTED_VALUE"""),"REWARD") -> REWARD | F32: =IFERROR(__xludf.DUMMYFUNCTION("""COMPUTED_VALUE"""),10.0) -> 10 | G32: =IFERROR(__xludf.DUMMYFUNCTION("""COMPUTED_VALUE"""),40.0) -> 40 | H32: =IFERROR(__xludf.DUMMYFUNCTION("""COMPUTED_VALUE"""),50.0) -> 50 | K32: =IFERROR(__xludf.DUMMYFUNCTION("""COMPUTED_VALUE"""),"On-time attendance reward") -> On-time attendance reward | L32: =IFERROR(__xludf.DUMMYFUNCTION("""COMPUTED_VALUE"""),"Success") -> Success
A33: =IFERROR(__xludf.DUMMYFUNCTION("""COMPUTED_VALUE"""),46168.3559375) -> 46168.356 | B33: =IFERROR(__xludf.DUMMYFUNCTION("""COMPUTED_VALUE"""),46168.0) -> 46168 | C33: =IFERROR(__xludf.DUMMYFUNCTION("""COMPUTED_VALUE"""),"5a032611") -> 5a032611 | D33: =IFERROR(__xludf.DUMMYFUNCTION("""COMPUTED_VALUE"""),"Harold Dou") -> Harold Dou | E33: =IFERROR(__xludf.DUMMYFUNCTION("""COMPUTED_VALUE"""),"REWARD") -> REWARD | F33: =IFERROR(__xludf.DUMMYFUNCTION("""COMPUTED_VALUE"""),10.0) -> 10 | G33: =IFERROR(__xludf.DUMMYFUNCTION("""COMPUTED_VALUE"""),40.0) -> 40 | H33: =IFERROR(__xludf.DUMMYFUNCTION("""COMPUTED_VALUE"""),50.0) -> 50 | K33: =IFERROR(__xludf.DUMMYFUNCTION("""COMPUTED_VALUE"""),"On-time attendance reward") -> On-time attendance reward | L33: =IFERROR(__xludf.DUMMYFUNCTION("""COMPUTED_VALUE"""),"Success") -> Success
A34: =IFERROR(__xludf.DUMMYFUNCTION("""COMPUTED_VALUE"""),46168.35628472222) -> 46168.356 | B34: =IFERROR(__xludf.DUMMYFUNCTION("""COMPUTED_VALUE"""),46168.0) -> 46168 | C34: =IFERROR(__xludf.DUMMYFUNCTION("""COMPUTED_VALUE"""),"9a5f2811") -> 9a5f2811 | D34: =IFERROR(__xludf.DUMMYFUNCTION("""COMPUTED_VALUE"""),"Junyoung Yoo") -> Junyoung Yoo | E34: =IFERROR(__xludf.DUMMYFUNCTION("""COMPUTED_VALUE"""),"REWARD") -> REWARD | F34: =IFERROR(__xludf.DUMMYFUNCTION("""COMPUTED_VALUE"""),10.0) -> 10 | G34: =IFERROR(__xludf.DUMMYFUNCTION("""COMPUTED_VALUE"""),30.0) -> 30 | H34: =IFERROR(__xludf.DUMMYFUNCTION("""COMPUTED_VALUE"""),40.0) -> 40 | K34: =IFERROR(__xludf.DUMMYFUNCTION("""COMPUTED_VALUE"""),"On-time attendance reward") -> On-time attendance reward | L34: =IFERROR(__xludf.DUMMYFUNCTION("""COMPUTED_VALUE"""),"Success") -> Success
